Workbook

Sheet 权重
A14: CA | B14: Passing | C14: Crossing | D14: Marking | E14: Penalty taking | F14: Technique | G14: Corners | H14: Long Throw | I14: Dribbling | J14: Tackling | K14: Free Kick Taking | L14: Finishing | M14: First touch | N14: Heading | O14: Longshot | P14: Flair | Q14: Positioning | R14: Work rate | S14: Concentration | T14: Decision | U14: Leadership | V14: Aggression | W14: Vision | X14: Teamwork | Y14: Off the ball | Z14: Determination | AA14: Bravery | AB14: Anticipation | AC14: Composure | AD14: Acceleration | AE14: Jumping reach | AF14: Agility | AG14: Stamina | AH14: Balance | AI14: Strengh | AJ14: Pace | AK14: Natual fitness | AL14: consistency | AM14: important Matches | AN14: pressure
A15: CA | B15: 传球 | C15: 传中 | D15: 盯人 | E15: 罚点球 | F15: 技术 | G15: 角球 | H15: 界外球 | I15: 盘带 | J15: 抢断 | K15: 任意球 | L15: 射门 | M15: 停球 | N15: 头球 | O15: 远射 | P15: 才华 | Q15: 防守站位 | R15: 工作投入 | S15: 集中 | T15: 决断 | U15: 领导力 | V15: 侵略性 | W15: 视野 | X15: 团队合作 | Y15: 无球跑动 | Z15: 意志力 | AA15: 勇敢 | AB15: 预判 | AC15: 镇定 | AD15: 爆发力 | AE15: 弹跳 | AF15: 灵活 | AG15: 耐力 | AH15: 平衡 | AI15: 强壮 | AJ15: 速度 | AK15: 体质 | AL15: 稳定 | AM15: 大赛 | AN15: 抗压能力 | BO15: 表3： | BP15: attribute=18 - attribute=1 | BX15: 表5： | BY15: attribute=18 - attribute=6 | CG15: 表6： | CH15: attribute=6 - attribute=1
A16: 这是从12降低到6 | B16: 0.5 | C16: 2.4 | D16: 1.63 | E16: 0 | F16: -0.1 | G16: 0 | H16: 0 | I16: -9.2 | J16: 3.7 | K16: 0 | L16: -2.2 | M16: -0.1 | N16: 0.5 | O16: -0.5 | Q16: 2.6 | S16: -4.5 | T16: 4.6 | W16: 3.9 | Y16: 0.2 | AB16: -5.3 | AC16: -0.8 | AD16: -34.6 | AE16: -8.3 | AF16: 2 | AG16: -5 | AH16: -10.1 | AI16: -7.7 | AJ16: -29.9 | AK16: -9.2 | AO16: 这是从12降低到6 | BP16: change of Win rate | BR16: change of Win rate | BT16: change of Win rate | BY16: change of Win rate | CA16: change of Win rate | CC16: change of Win rate | CH16: change of Win rate | CJ16: change of Win rate | CL16: change of Win rate
BP17: 胜率的改变量 | BR17: 胜率的改变量 | BT17: 胜率的改变量 | BY17: 胜率的改变量 | CA17: 胜率的改变量 | CC17: 胜率的改变量 | CH17: 胜率的改变量 | CJ17: 胜率的改变量 | CL17: 胜率的改变量
A18: CA | B18: Passing | C18: Crossing | D18: Marking | E18: Penalty taking | F18: Technique | G18: Corners | H18: Long Throw | I18: Dribbling | J18: Tackling | K18: Free Kick Taking | L18: Finishing | M18: First touch | N18: Heading | O18: Longshot | P18: Flair | Q18: Positioning | R18: Work rate | S18: Concentration | T18: Decision | U18: Leadership | V18: Aggression | W18: Vision | X18: Teamwork | Y18: Off the ball | Z18: Determination | AA18: Bravery | AB18: Anticipation | AC18: Composure | AD18: Acceleration | AE18: Jumping reach | AF18: Agility | AG18: Stamina | AH18: Balance | AI18: Strengh | AJ18: Pace | AK18: Natual fitness | AL18: consistency | AM18: important Matches | AN18: pressure | BO18: 传球Passing | BP18: 0.058659731 | BQ18: 才华Flair | BR18: -0.0019379845 | BS18: 爆发Acceleration | BT18: 0.77054264 | BX18: 传球Passing | BY18: 0.023194614 | BZ18: 才华Flair | CA18: 0.0089147287 | CB18: 爆发Acceleration | CC18: 0.57364341 | CG18: 传球Passing | CH18: 0.035465116 | CI18: 才华Flair | CJ18: -0.010852713 | CK18: 爆发Acceleration | CL18: 0.19689922
A19: CA | B19: 传球 | C19: 传中 | D19: 盯人 | E19: 罚点球 | F19: 技术 | G19: 角球 | H19: 界外球 | I19: 盘带 | J19: 抢断 | K19: 任意球 | L19: 射门 | M19: 停球 | N19: 头球 | O19: 远射 | P19: 才华 | Q19: 防守站位 | R19: 工作投入 | S19: 集中 | T19: 决断 | U19: 领导力 | V19: 侵略性 | W19: 视野 | X19: 团队合作 | Y19: 无球跑动 | Z19: 意志力 | AA19: 勇敢 | AB19: 预判 | AC19: 镇定 | AD19: 爆发力 | AE19: 弹跳 | AF19: 灵活 | AG19: 耐力 | AH19: 平衡 | AI19: 强壮 | AJ19: 速度 | AK19: 体质 | AL19: 稳定 | AM19: 大赛 | AN19: 抗压能力 | BO19: 传中Crossing | BP19: 0.030852713 | BQ19: 防守站位Positioning | BR19: 0.084496124 | BS19: 弹跳Jumping Reach | BT19: 0.28023256 | BX19: 传中Crossing | BY19: 0.0013953488 | BZ19: 防守站位Positioning | CA19: 0.013953488 | CB19: 弹跳Jumping Reach | CC19: 0.23837209 | CG19: 传中Crossing | CH19: 0.029457364 | CI19: 防守站位Positioning | CJ19: 0.070542636 | CK19: 弹跳Jumping Reach | CL19: 0.041860465
A20: 这是从10降低到6 | P20: 0.5 | R20: -8.8 | U20: -1.1 | V20: -0.9 | X20: 2.5 | Z20: 0.5 | AA20: 1.6 | AL20: -1.2 | AM20: -0.5 | AN20: -2.2 | AO20: 这是从10降低到6 | BO20: 盯人Marking | BP20: 0.024651163 | BQ20: 工作投入Work Rate | BR20: 0.59017442 | BS20: 灵活Agility | BT20: 0.19263566 | BX20: 盯人Marking | BY20: 0.016589147 | BZ20: 工作投入Work Rate | CA20: 0.14831395 | CB20: 灵活Agility | CC20: 0.037338501 | CG20: 盯人Marking | CH20: 0.0080620155 | CI20: 工作投入Work Rate | CJ20: 0.44186047 | CK20: 灵活Agility | CL20: 0.15529716
BO21: 罚点球 | BQ21: 集中Concentration | BR21: 0.23643411 | BS21: 耐力Stamina | BT21: 0.20852713 | BX21: 罚点球 | BZ21: 集中Concentration | CA21: 0.086046512 | CB21: 耐力Stamina | CC21: 0.081007752 | CG21: 罚点球 | CH21: 0 | CI21: 集中Concentration | CJ21: 0.1503876 | CK21: 耐力Stamina | CL21: 0.12751938
A22: CA | B22: Passing | C22: Crossing | D22: Marking | E22: Penalty taking | F22: Technique | G22: Corners | H22: Long Throw | I22: Dribbling | J22: Tackling | K22: Free Kick Taking | L22: Finishing | M22: First touch | N22: Heading | O22: Longshot | P22: Flair | Q22: Positioning | R22: Work rate | S22: Concentration | T22: Decision | U22: Leadership | V22: Aggression | W22: Vision | X22: Teamwork | Y22: Off the ball | Z22: Determination | AA22: Bravery | AB22: Anticipation | AC22: Composure | AD22: Acceleration | AE22: Jumping reach | AF22: Agility | AG22: Stamina | AH22: Balance | AI22: Strengh | AJ22: Pace | AK22: Natual fitness | AL22: consistency | AM22: important Matches | AN22: pressure | BO22: 技术Technique | BP22: -0.01161068 | BQ22: 决断Decisions | BR22: 0.0060465116 | BS22: 平衡Balance | BT22: 0.20465116 | BX22: 技术Technique | BY22: 0.024177433 | BZ22: 决断Decisions | CA22: -0.024186047 | CB22: 平衡Balance | CC22: 0.17170543 | CG22: 技术Technique | CH22: -0.035788114 | CI22: 决断Decisions | CJ22: 0.030232558 | CK22: 平衡Balance | CL22: 0.032945736
A23: CA | B23: 传球 | C23: 传中 | D23: 盯人 | E23: 罚点球 | F23: 技术 | G23: 角球 | H23: 界外球 | I23: 盘带 | J23: 抢断 | K23: 任意球 | L23: 射门 | M23: 停球 | N23: 头球 | O23: 远射 | P23: 才华 | Q23: 防守站位 | R23: 工作投入 | S23: 集中 | T23: 决断 | U23: 领导力 | V23: 侵略性 | W23: 视野 | X23: 团队合作 | Y23: 无球跑动 | Z23: 意志力 | AA23: 勇敢 | AB23: 预判 | AC23: 镇定 | AD23: 爆发力 | AE23: 弹跳 | AF23: 灵活 | AG23: 耐力 | AH23: 平衡 | AI23: 强壮 | AJ23: 速度 | AK23: 体质 | AL23: 稳定 | AM23: 大赛 | AN23: 抗压能力 | BO23: 角球 | BQ23: 领导力Leadership | BR23: 0.0024806202 | BS23: 强壮Strength | BT23: 0.11434109 | BX23: 角球 | BZ23: 领导力Leadership | CA23: 0.043178295 | CB23: 强壮Strength | CC23: 0.13410853 | CG23: 角球 | CI23: 领导力Leadership | CJ23: -0.040697674 | CK23: 强壮Strength | CL23: -0.019767442
A24: 这是从12降低到1 | B24: -3.1 | C24: -0.5 | D24: 0.8 | E24: 0 | F24: 3.5 | G24: 0 | H24: 0 | I24: -15.2 | J24: 0.2 | K24: 0 | L24: -7.6 | M24: 0.5 | N24: -1.8 | O24: -1.7 | Q24: -4.5 | S24: -19.5 | T24: 1.6 | W24: -3.1 | Y24: 0 | AB24: -12.6 | AC24: -8.6 | AD24: -54.3 | AE24: -12.4 | AF24: -13.5 | AG24: -17.7 | AH24: -13.4 | AI24: -5.7 | AJ24: -53.6 | AK24: -4.6 | AO24: 这是从12降低到1 | BO24: 界外球 | BQ24: 侵略性Aggression | BR24: 0.084186047 | BS24: 速度Pace | BT24: 0.76918605 | BX24: 界外球 | BZ24: 侵略性Aggression | CA24: 0.029922481 | CB24: 速度Pace | CC24: 0.53236434 | CG24: 界外球 | CI24: 侵略性Aggression | CJ24: 0.054263566 | CK24: 速度Pace | CL24: 0.23682171
BO25: 盘带Dribbling | BP25: 0.23410853 | BQ25: 视野Vision | BR25: 0.042945736 | BS25: 体质 | BT25: 0.11007752 | BX25: 盘带Dribbling | BY25: 0.17403101 | BZ25: 视野Vision | CA25: -0.026821705 | CB25: 体质 | CC25: 0.063565891 | CG25: 盘带Dribbling | CH25: 0.060077519 | CI25: 视野Vision | CJ25: 0.069767442 | CK25: 体质Natual fitness | CL25: 0.046511628
A26: CA | B26: Passing | C26: Crossing | D26: Marking | E26: Penalty taking | F26: Technique | G26: Corners | H26: Long Throw | I26: Dribbling | J26: Tackling | K26: Free Kick Taking | L26: Finishing | M26: First touch | N26: Heading | O26: Longshot | P26: Flair | Q26: Positioning | R26: Work rate | S26: Concentration | T26: Decision | U26: Leadership | V26: Aggression | W26: Vision | X26: Teamwork | Y26: Off the ball | Z26: Determination | AA26: Bravery | AB26: Anticipation | AC26: Composure | AD26: Acceleration | AE26: Jumping reach | AF26: Agility | AG26: Stamina | AH26: Balance | AI26: Strengh | AJ26: Pace | AK26: Natual fitness | AL26: consistency | AM26: important Matches | AN26: pressure | BO26: 抢断Tackling | BP26: 0.027364341 | BQ26: 团队合作Teamwork | BR26: 0.0040310078 | BS26: 稳定consistency | BT26: 0.051937984 | BX26: 抢断Tackling | BY26: -0.007751938 | BZ26: 团队合作Teamwork | CA26: -0.016124031 | CB26: 稳定consistency | CC26: 0.046511628 | CG26: 抢断Tackling | CH26: 0.035116279 | CI26: 团队合作Teamwork | CJ26: 0.020155039 | CK26: 稳定consistency | CL26: 0.0054263566
A27: CA | B27: 传球 | C27: 传中 | D27: 盯人 | E27: 罚点球 | F27: 技术 | G27: 角球 | H27: 界外球 | I27: 盘带 | J27: 抢断 | K27: 任意球 | L27: 射门 | M27: 停球 | N27: 头球 | O27: 远射 | P27: 才华 | Q27: 防守站位 | R27: 工作投入 | S27: 集中 | T27: 决断 | U27: 领导力 | V27: 侵略性 | W27: 视野 | X27: 团队合作 | Y27: 无球跑动 | Z27: 意志力 | AA27: 勇敢 | AB27: 预判 | AC27: 镇定 | AD27: 爆发力 | AE27: 弹跳 | AF27: 灵活 | AG27: 耐力 | AH27: 平衡 | AI27: 强壮 | AJ27: 速度 | AK27: 体质 | AL27: 稳定 | AM27: 大赛 | AN27: 抗压能力 | BO27: 任意球 | BQ27: 无球跑动Off The Ball | BR27: 0.01627907 | BS27: 大赛important Matches | BT27: 0.056589147 | BX27: 任意球 | BZ27: 无球跑动Off The Ball | CA27: 0.014728682 | CB27: 大赛important Matches | CC27: 0.034108527 | CG27: 任意球 | CI27: 无球跑动Off The Ball | CJ27: 0.0015503876 | CK27: 大赛important Matches | CL27: 0.02248062
A28: 这是从10降低到1 | P28: 1.6 | R28: -53 | U28: 3 | V28: -6.4 | X28: 0.5 | Z28: -7 | AA28: 1.7 | AL28: -1.8 | AM28: -2.7 | AN28: -20.5 | AO28: 这是从10降低到6 | BO28: 射门Finishing | BP28: 0.11558338 | BQ28: 意志力Determination | BR28: 0.11674419 | BS28: 抗压能力pressure | BT28: 0.27131783 | BX28: 射门Finishing | BY28: 0.062095011 | BZ28: 意志力Determination | CA28: 0.042325581 | CB28: 抗压能力pressure | CC28: 0.089147287 | CG28: 射门Finishing | CH28: 0.053488372 | CI28: 意志力Determination | CJ28: 0.074418605 | CK28: 抗压能力pressure | CL28: 0.18217054
BO29: 停球First Touch | BP29: 0.03250646 | BQ29: 勇敢Bravery | BR29: -0.0035658915 | BX29: 停球First Touch | BY29: 0.038449612 | BZ29: 勇敢Bravery | CA29: -0.0020155039 | CG29: 停球First Touch | CH29: -0.0059431525 | CI29: 勇敢Bravery | CJ29: -0.0015503876
A30: CA | B30: Passing | C30: Crossing | D30: Marking | E30: Penalty taking | F30: Technique | G30: Corners | H30: Long Throw | I30: Dribbling | J30: Tackling | K30: Free Kick Taking | L30: Finishing | M30: First touch | N30: Heading | O30: Longshot | P30: Flair | Q30: Positioning | R30: Work rate | S30: Concentration | T30: Decision | U30: Leadership | V30: Aggression | W30: Vision | X30: Teamwork | Y30: Off the ball | Z30: Determination | AA30: Bravery | AB30: Anticipation | AC30: Composure | AD30: Acceleration | AE30: Jumping reach | AF30: Agility | AG30: Stamina | AH30: Balance | AI30: Strengh | AJ30: Pace | AK30: Natual fitness | AL30: consistency | AM30: important Matches | AN30: pressure | BO30: 头球Heading | BP30: 0.045839793 | BQ30: 预判Anticipation | BR30: 0.18 | BX30: 头球Heading | BY30: 0.023100775 | BZ30: 预判Anticipation | CA30: 0.10713178 | CG30: 头球Heading | CH30: 0.022739018 | CI30: 预判Anticipation | CJ30: 0.072868217
A31: CA | B31: 传球 | C31: 传中 | D31: 盯人 | E31: 罚点球 | F31: 技术 | G31: 角球 | H31: 界外球 | I31: 盘带 | J31: 抢断 | K31: 任意球 | L31: 射门 | M31: 停球 | N31: 头球 | O31: 远射 | P31: 才华 | Q31: 防守站位 | R31: 工作投入 | S31: 集中 | T31: 决断 | U31: 领导力 | V31: 侵略性 | W31: 视野 | X31: 团队合作 | Y31: 无球跑动 | Z31: 意志力 | AA31: 勇敢 | AB31: 预判 | AC31: 镇定 | AD31: 爆发力 | AE31: 弹跳 | AF31: 灵活 | AG31: 耐力 | AH31: 平衡 | AI31: 强壮 | AJ31: 速度 | AK31: 体质 | AL31: 稳定 | AM31: 大赛 | AN31: 抗压能力 | BO31: 远射Long Shots | BP31: 0.067131783 | BQ31: 镇定Composure | BR31: 0.1079845 | BX31: 远射Long Shots | BY31: 0.054728682 | BZ31: 镇定Composure | CA31: 0.030852713 | CG31: 远射Long Shots | CH31: 0.012403101 | CI31: 镇定Composure | CJ31: 0.077131783
A32: 这是从12增加到18 | B32: 2.8 | C32: 2.5 | D32: 3.3 | E32: 0 | F32: 2.3 | G32: 0 | H32: 0 | I32: 8.2 | J32: 3 | K32: 0 | L32: 4 | M32: 3.8 | N32: 2.8 | O32: 5 | Q32: 4 | S32: 4.1 | T32: 2.2 | W32: 1.2 | Y32: 1.6 | AB32: 5.4 | AC32: 2.2 | AD32: 22.7 | AE32: 15.6 | AF32: 5.8 | AG32: 3.1 | AH32: 7 | AI32: 5.7 | AJ32: 23.4 | AK32: 1.8 | AO32: 这是从12增加到18
BO33: 将表1的值减去表2，可以得到“属性18和属性1”之间的胜率差： | BX33: 将表1的值减去表4，可以得到“属性18和属性6”之间的胜率差： | CG33: 将表4的值减去表2，可以得到“属性6和属性1”之间的胜率差：
A34: CA | B34: Passing | C34: Crossing | D34: Marking | E34: Penalty taking | F34: Technique | G34: Corners | H34: Long Throw | I34: Dribbling | J34: Tackling | K34: Free Kick Taking | L34: Finishing | M34: First touch | N34: Heading | O34: Longshot | P34: Flair | Q34: Positioning | R34: Work rate | S34: Concentration | T34: Decision | U34: Leadership | V34: Aggression | W34: Vision | X34: Teamwork | Y34: Off the ball | Z34: Determination | AA34: Bravery | AB34: Anticipation | AC34: Composure | AD34: Acceleration | AE34: Jumping reach | AF34: Agility | AG34: Stamina | AH34: Balance | AI34: Strengh | AJ34: Pace | AK34: Natual fitness | AL34: consistency | AM34: important Matches | AN34: pressure | BO34: Table 1 - Table 2 | BX34: Table 1 - Table 4 | CG34: Table 4 - Table 2
A35: CA | B35: 传球 | C35: 传中 | D35: 盯人 | E35: 罚点球 | F35: 技术 | G35: 角球 | H35: 界外球 | I35: 盘带 | J35: 抢断 | K35: 任意球 | L35: 射门 | M35: 停球 | N35: 头球 | O35: 远射 | P35: 才华 | Q35: 防守站位 | R35: 工作投入 | S35: 集中 | T35: 决断 | U35: 领导力 | V35: 侵略性 | W35: 视野 | X35: 团队合作 | Y35: 无球跑动 | Z35: 意志力 | AA35: 勇敢 | AB35: 预判 | AC35: 镇定 | AD35: 爆发力 | AE35: 弹跳 | AF35: 灵活 | AG35: 耐力 | AH35: 平衡 | AI35: 强壮 | AJ35: 速度 | AK35: 体质 | AL35: 稳定 | AM35: 大赛 | AN35: 抗压能力
A36: 这是从10增加到18 | P36: 1.4 | R36: 6 | U36: 3.2 | V36: 2.1 | X36: 0.9 | Z36: 4.7 | AA36: 1.4 | AL36: 3.4 | AM36: 3 | AN36: 6.7 | AO36: 这是从10增加到18
A38: CA | B38: Passing | C38: Crossing | D38: Marking | E38: Penalty taking | F38: Technique | G38: Corners | H38: Long Throw | I38: Dribbling | J38: Tackling | K38: Free Kick Taking | L38: Finishing | M38: First touch | N38: Heading | O38: Longshot | P38: Flair | Q38: Positioning | R38: Work rate | S38: Concentration | T38: Decision | U38: Leadership | V38: Aggression | W38: Vision | X38: Teamwork | Y38: Off the ball | Z38: Determination | AA38: Bravery | AB38: Anticipation | AC38: Composure | AD38: Acceleration | AE38: Jumping reach | AF38: Agility | AG38: Stamina | AH38: Balance | AI38: Strengh | AJ38: Pace | AK38: Natual fitness | AL38: consistency | AM38: important Matches | AN38: pressure
A39: CA | B39: 传球 | C39: 传中 | D39: 盯人 | E39: 罚点球 | F39: 技术 | G39: 角球 | H39: 界外球 | I39: 盘带 | J39: 抢断 | K39: 任意球 | L39: 射门 | M39: 停球 | N39: 头球 | O39: 远射 | P39: 才华 | Q39: 防守站位 | R39: 工作投入 | S39: 集中 | T39: 决断 | U39: 领导力 | V39: 侵略性 | W39: 视野 | X39: 团队合作 | Y39: 无球跑动 | Z39: 意志力 | AA39: 勇敢 | AB39: 预判 | AC39: 镇定 | AD39: 爆发力 | AE39: 弹跳 | AF39: 灵活 | AG39: 耐力 | AH39: 平衡 | AI39: 强壮 | AJ39: 速度 | AK39: 体质 | AL39: 稳定 | AM39: 大赛 | AN39: 抗压能力
A40: 这是从1增加到6 | B40: 3.5 | C40: 2.9 | D40: 0.8 | E40: 0 | F40: -3.6 | G40: 0 | H40: 0 | I40: 6 | J40: 3.5 | K40: 0 | L40: 5.3 | M40: -0.6 | N40: 2.3 | O40: 1.2 | P40: -1.1 | Q40: 7.1 | R40: 44.2 | S40: 15 | T40: 3 | U40: -4.1 | V40: 5.4 | W40: 7 | X40: 2 | Y40: 0.2 | Z40: 7.4 | AA40: -0.2 | AB40: 7.3 | AC40: 7.7 | AD40: 19.7 | AE40: 4.2 | AF40: 15.5 | AG40: 12.8 | AH40: 3.3 | AI40: -2 | AJ40: 23.7 | AK40: 4.7 | AL40: 0.5 | AM40: 2.2 | AN40: 18.2 | AO40: 这是从1增加到6（这是通过表4和表2，两个表，相减减出来的）
B46: Passing | C46: Crossing | D46: Marking | E46: Penalty taking | F46: Technique | G46: Corners | H46: Long Throw | I46: Dribbling | J46: Tackling | K46: Free Kick Taking | L46: Finishing | M46: First touch | N46: Heading | O46: Longshot | P46: Flair | Q46: Positioning | R46: Work rate | S46: Concentration | T46: Decision | U46: Leadership | V46: Aggression | W46: Vision | X46: Teamwork | Y46: Off the ball | Z46: Determination | AA46: Bravery | AB46: Anticipation | AC46: Composure | AD46: Acceleration | AE46: Jumping reach | AF46: Agility | AG46: Stamina | AH46: Balance | AI46: Strengh | AJ46: Pace | AK46: Natual fitness | AL46: consistency | AM46: important Matches | AN46: pressure
B47: 传球 | C47: 传中 | D47: 盯人 | E47: 罚点球 | F47: 技术 | G47: 角球 | H47: 界外球 | I47: 盘带 | J47: 抢断 | K47: 任意球 | L47: 射门 | M47: 停球 | N47: 头球 | O47: 远射 | P47: 才华 | Q47: 防守站位 | R47: 工作投入 | S47: 集中 | T47: 决断 | U47: 领导力 | V47: 侵略性 | W47: 视野 | X47: 团队合作 | Y47: 无球跑动 | Z47: 意志力 | AA47: 勇敢 | AB47: 预判 | AC47: 镇定 | AD47: 爆发力 | AE47: 弹跳 | AF47: 灵活 | AG47: 耐力 | AH47: 平衡 | AI47: 强壮 | AJ47: 速度 | AK47: 体质 | AL47: 稳定 | AM47: 大赛 | AN47: 抗压能力
A48: 从1至6每点属性贡献 | B48: =B40/5 -> 0.7 | C48: =C40/5 -> 0.58 | D48: =D40/5 -> 0.16 | E48: =E40/5 -> 0 | F48: =F40/5 -> -0.72 | G48: =G40/5 -> 0 | H48: =H40/5 -> 0 | I48: =I40/5 -> 1.2 | ... AC48: =AC40/5 -> 1.54 | AD48: =AD40/5*1.25 -> 4.925 | AE48: =AE40/5 -> 0.84 | AF48: =AF40/5 -> 3.1 | AG48: =AG40/5 -> 2.56 | AH48: =AH40/5 -> 0.66 | AI48: =AI40/5 -> -0.4 | AJ48: =AJ40/5*1.25 -> 5.925 | AK48: =AK40/5 -> 0.94 | AL48: =AL40/5 -> 0.1 | AM48: =AM40/5 -> 0.44 | AN48: =AN40/5 -> 3.64 | AO48: 从1至6每点属性贡献 | AR48: 注意，（速度，爆发）分别*1.25
A49: 从6至12每点属性贡献 | B49: =-B16/6 -> -0.083333333 | C49: =-C16/6 -> -0.4 | D49: =-D16/6 -> -0.27166667 | E49: =-E16/6 -> 0 | F49: =-F16/6 -> 0.016666667 | G49: =-G16/6 -> 0 | H49: =-H16/6 -> 0 | I49: =-I16/6 -> 1.5333333 | ... O49: =-O16/6 -> 0.083333333 | Q49: =-Q16/6 -> -0.43333333 | S49: =-S16/6 -> 0.75 | T49: =-T16/6 -> -0.76666667 | W49: =-W16/6 -> -0.65 | Y49: =-Y16/6 -> -0.033333333 | AB49: =-AB16/6 -> 0.88333333 | AC49: =-AC16/6 -> 0.13333333 | AD49: =-AD16/6*1.25 -> 7.2083333 | AE49: =-AE16/6 -> 1.3833333 | AF49: =-AF16/6 -> -0.33333333 | AG49: =-AG16/6 -> 0.83333333 | AH49: =-AH16/6 -> 1.6833333 | AI49: =-AI16/6 -> 1.2833333 | AJ49: =-AJ16/6*1.25 -> 6.2291667 | AK49: =-AK16/6 -> 1.5333333 | AO49: 从6至12每点属性贡献 | AR49: 注意，（速度，爆发）分别*1.25
A50: 从6至10每点属性贡献 | P50: =-P20/4 -> -0.125 | R50: =-R20/4 -> 2.2 | U50: =-U20/4 -> 0.275 | V50: =-V20/4 -> 0.225 | X50: =-X20/4 -> -0.625 | Z50: =-Z20/4 -> -0.125 | AA50: =-AA20/4 -> -0.4 | AL50: =-AL20/4 -> 0.3 | AM50: =-AM20/4 -> 0.125 | AN50: =-AN20/4 -> 0.55 | AO50: 从6至10每点属性贡献 | AR50: 注意，（速度，爆发）分别*1.25
A51: 从12至18每点属性贡献 | B51: =B32/6 -> 0.46666667 | C51: =C32/6 -> 0.41666667 | D51: =D32/6 -> 0.55 | E51: =E32/6 -> 0 | F51: =F32/6 -> 0.38333333 | G51: =G32/6 -> 0 | H51: =H32/6 -> 0 | I51: =I32/6 -> 1.3666667 | ... O51: =O32/6 -> 0.83333333 | Q51: =Q32/6 -> 0.66666667 | S51: =S32/6 -> 0.68333333 | T51: =T32/6 -> 0.36666667 | W51: =W32/6 -> 0.2 | Y51: =Y32/6 -> 0.26666667 | AB51: =AB32/6 -> 0.9 | AC51: =AC32/6 -> 0.36666667 | AD51: =AD32/6*1.25 -> 4.7291667 | AE51: =AE32/6 -> 2.6 | AF51: =AF32/6 -> 0.96666667 | AG51: =AG32/6 -> 0.51666667 | AH51: =AH32/6 -> 1.1666667 | AI51: =AI32/6 -> 0.95 | AJ51: =AJ32/6*1.25 -> 4.875 | AK51: =AK32/6 -> 0.3 | AO51: 从12至18每点属性贡献 | AR51: 注意，（速度，爆发）分别*1.25
A52: 从10至18每点属性贡献 | P52: =P36/8 -> 0.175 | R52: =R36/8 -> 0.75 | U52: =U36/8 -> 0.4 | V52: =V36/8 -> 0.2625 | X52: =X36/8 -> 0.1125 | Z52: =Z36/8 -> 0.5875 | AA52: =AA36/8 -> 0.175 | AL52: =AL36/8 -> 0.425 | AM52: =AM36/8 -> 0.375 | AN52: =AN36/8 -> 0.8375 | AO52: 从10至18每点属性贡献 | AR52: 注意，（速度，爆发）分别*1.25
B58: 判定逻辑： | D58: （多数属性）如果属性≤6，（属性-1）*（从1至6每点属性贡献）。
D59: 否则，如果属性≤12，{5*（从1至6每点属性贡献）+ （属性-6）*（从6至12每点属性贡献）}
D60: 否则，即＞12，{5*（从1至6每点属性贡献）+ 6*（从6至12每点属性贡献）+ （属性-12）*（从12至18每点属性贡献）}
D61: 忽略18-20的权重因为没测这一段，这一段的权重继续使用12至18的贡献
B63: 另外，如果是 才华、工作投入、领导力、侵略性、团队合作、意志、勇敢
D65: （多数属性）如果属性≤6，（属性-1）*（从1至6每点属性贡献）。
D66: 否则，如果属性≤10，{5*（从1至6每点属性贡献）+ （属性-4）*（从6至10每点属性贡献）}
...

Sheet 数据
A1: 位​置/角​色/职​责 | C1: 球​员 | D1: 现​状 | F1: 疲劳值(N) | G1: 士​气 | H1: 位​置 | I1: 年​龄 | J1: 能​力 | K1: 潜​力 | L1: 传​球 | M1: 传​中 | N1: 盯​人 | O1: 点​球 | P1: 技​术 | Q1: 角​球 | R1: 界​外球 | S1: 盘​带 | T1: 抢​断 | U1: 任​意球 | V1: 射​门 | W1: 停​球 | X1: 头​球 | Y1: 远​射 | Z1: 才​华 | AA1: 位​置 | AB1: 投​入 | AC1: 集​中 | AD1: 决​断 | AE1: 领​导力 | AF1: 侵​略 | AG1: 视​野 | AH1: 合​作 | AI1: 无​球跑 | AJ1: 意​志 | AK1: 勇​敢 | AL1: 预​判 | AM1: 镇​定 | AN1: 爆​发 | AO1: 弹​跳 | AP1: 灵​活 | AQ1: 耐​力 | AR1: 平​衡 | AS1: 强​壮 | AT1: 速​度 | AU1: 体​质 | AV1: 稳​定 | AW1: 大​赛发​挥 | AX1: 抗​压 | AY1: 出​击 | AZ1: 开​球 | BA1: 反​应 | BB1: 拦​截传​中 | BC1: 击​球 | BD1: 手​控球 | BE1: 手​抛球 | BF1: 一​对一 | BG1: 意​外 | BH1: 指​挥 | BI1: 制​空 | BJ1: 平​均评​分 | BK1: 体​况 | BL1: 职​业素​养 | BM1: 出​场 | BN1: 总​体满​意度 | BO1: 总​联赛​进球 | BP1: 到​期 | BQ1: 训​练负​荷 | BR1: 总​体风​险
A2: - | C2: 汤姆·希顿 - 选​择球​员 | D2: 度​假 | E2: 1 | F2: 0 | G2: 有​点差 | H2: 门​将 | I2: 39 | J2: 120 | K2: 150 | L2: 12 | M2: 2 | N2: 2 | O2: 3 | P2: 8 | Q2: 2 | R2: 2 | S2: 2 | T2: 3 | U2: 5 | V2: 2 | W2: 8 | X2: 8 | Y2: 3 | Z2: 1 | AA2: 14 | AB2: 6 | AC2: 17 | AD2: 14 | AE2: 18 | AF2: 7 | AG2: 11 | AH2: 18 | AI2: 2 | AJ2: 13 | AK2: 14 | AL2: 12 | AM2: 10 | AN2: 5 | AO2: 14 | AP2: 11 | AQ2: 8 | AR2: 10 | AS2: 12 | AT2: 5 | AU2: 13 | AV2: 14 | AW2: 16 | AX2: 11 | AY2: 11 | AZ2: 10 | BA2: 12 | BB2: 15 | BC2: 5 | BD2: 13 | BE2: 11 | BF2: 12 | BG2: 6 | BH2: 16 | BI2: 14 | BJ2: - | BK2: 完​美 | BL2: 17 | BM2: - | BO2: - | BP2: 46203 | BQ2: 无 | BR2: 低​伤病​风险
A3: - | C3: 利桑德罗·马丁内斯 - 选​择球​员 | D3: 度​假 | E3: 1 | F3: 0 | G3: 稍​差 | H3: 后​卫 (左中) | I3: 27 | J3: 152 | K3: 160 | L3: 15 | M3: 9 | N3: 16 | O3: 10 | P3: 15 | Q3: 6 | R3: 12 | S3: 9 | T3: 16 | U3: 8 | V3: 7 | W3: 15 | X3: 13 | Y3: 6 | Z3: 10 | AA3: 16 | AB3: 15 | AC3: 14 | AD3: 13 | AE3: 14 | AF3: 18 | AG3: 14 | AH3: 14 | AI3: 8 | AJ3: 17 | AK3: 17 | AL3: 16 | AM3: 16 | AN3: 12 | AO3: 12 | AP3: 14 | AQ3: 15 | AR3: 14 | AS3: 15 | AT3: 12 | AU3: 15 | AV3: 13 | AW3: 11 | AX3: 14 | AY3: 3 | AZ3: 1 | BA3: 1 | BB3: 3 | BC3: 3 | BD3: 1 | BE3: 1 | BF3: 1 | BG3: 3 | BH3: 2 | BI3: 2 | BJ3: - | BK3: 完​美 | BL3: 14 | BM3: - | BO3: 10 | BP3: 46568 | BQ3: 无 | BR3: 低​伤病​风险
A4: - | C4: 瑟内·拉门斯 - 选​择球​员 | D4: 度​假 | E4: 1 | F4: 0 | G4: 很​好 | H4: 门​将 | I4: 22 | J4: 138 | K4: 155 | L4: 13 | M4: 2 | N4: 7 | O4: 1 | P4: 12 | Q4: 6 | R4: 2 | S4: 2 | T4: 13 | U4: 9 | V4: 1 | W4: 14 | X4: 12 | Y4: 3 | Z4: 1 | AA4: 13 | AB4: 13 | AC4: 14 | AD4: 13 | AE4: 12 | AF4: 5 | AG4: 11 | AH4: 12 | AI4: 12 | AJ4: 18 | AK4: 13 | AL4: 13 | AM4: 14 | AN4: 12 | AO4: 14 | AP4: 16 | AQ4: 12 | AR4: 10 | AS4: 11 | AT4: 11 | AU4: 12 | AV4: 14 | AW4: 13 | AX4: 14 | AY4: 10 | AZ4: 14 | BA4: 15 | BB4: 13 | BC4: 10 | BD4: 13 | BE4: 12 | BF4: 13 | BG4: 4 | BH4: 13 | BI4: 15 | BJ4: - | BK4: 完​美 | BL4: 15 | BM4: - | BO4: - | BP4: 47664 | BQ4: 无 | BR4: 低​伤病​风险
A5: - | C5: 卡塞米罗 - 选​择球​员 | D5: 度​假 | E5: 1 | F5: 0 | G5: 还​可以 | H5: 后​腰, 中​场 (中) | I5: 33 | J5: 146 | K5: 170 | L5: 14 | M5: 11 | N5: 14 | O5: 14 | P5: 14 | Q5: 9 | R5: 10 | S5: 10 | T5: 17 | U5: 10 | V5: 11 | W5: 15 | X5: 17 | Y5: 14 | Z5: 12 | AA5: 14 | AB5: 14 | AC5: 14 | AD5: 12 | AE5: 17 | AF5: 18 | AG5: 14 | AH5: 17 | AI5: 13 | AJ5: 17 | AK5: 17 | AL5: 17 | AM5: 11 | AN5: 9 | AO5: 15 | AP5: 10 | AQ5: 12 | AR5: 15 | AS5: 17 | AT5: 10 | AU5: 12 | AV5: 13 | AW5: 15 | AX5: 15 | AY5: 3 | AZ5: 1 | BA5: 2 | BB5: 3 | BC5: 2 | BD5: 1 | BE5: 1 | BF5: 3 | BG5: 2 | BH5: 3 | BI5: 3 | BJ5: - | BK5: 完​美 | BL5: 16 | BM5: - | BO5: 38 | BP5: 46203 | BQ5: 无 | BR5: 低​伤病​风险
A6: - | C6: 马特乌斯·库尼亚 - 选​择球​员 | D6: 度​假 | E6: 1 | F6: 0 | G6: 好 | H6: 攻​中场 (右左中), 前​锋 (中) | I6: 26 | J6: 152 | K6: 162 | L6: 14 | M6: 13 | N6: 4 | O6: 13 | P6: 16 | Q6: 13 | R6: 5 | S6: 18 | T6: 6 | U6: 13 | V6: 15 | W6: 12 | X6: 11 | Y6: 15 | Z6: 17 | AA6: 5 | AB6: 15 | AC6: 7 | AD6: 11 | AE6: 10 | AF6: 16 | AG6: 12 | AH6: 10 | AI6: 13 | AJ6: 16 | AK6: 15 | AL6: 11 | AM6: 14 | AN6: 15 | AO6: 12 | AP6: 15 | AQ6: 13 | AR6: 15 | AS6: 12 | AT6: 15 | AU6: 12 | AV6: 10 | AW6: 14 | AX6: 12 | AY6: 2 | AZ6: 2 | BA6: 2 | BB6: 2 | BC6: 3 | BD6: 2 | BE6: 1 | BF6: 2 | BG6: 2 | BH6: 3 | BI6: 2 | BJ6: - | BK6: 完​美 | BL6: 11 | BM6: - | BO6: 32 | BP6: 47664 | BQ6: 无 | BR6: 低​伤病​风险
A7: - | C7: 帕特里克·多尔古 - 选​择球​员 | D7: 度​假 | E7: 1 | F7: 0 | G7: 较​好 | H7: 后​卫/边翼​卫/中​场 (左), 攻​中场 (右) | I7: 20 | J7: 139 | K7: 158 | L7: 11 | M7: 12 | N7: 8 | O7: 10 | P7: 13 | Q7: 7 | R7: 7 | S7: 13 | T7: 12 | U7: 9 | V7: 11 | W7: 13 | X7: 10 | Y7: 7 | Z7: 11 | AA7: 11 | AB7: 15 | AC7: 13 | AD7: 9 | AE7: 7 | AF7: 14 | AG7: 10 | AH7: 13 | AI7: 15 | AJ7: 15 | AK7: 10 | AL7: 13 | AM7: 10 | AN7: 16 | AO7: 12 | AP7: 12 | AQ7: 15 | AR7: 11 | AS7: 14 | AT7: 16 | AU7: 13 | AV7: 12 | AW7: 12 | AX7: 6 | AY7: 1 | AZ7: 3 | BA7: 2 | BB7: 2 | BC7: 2 | BD7: 2 | BE7: 1 | BF7: 1 | BG7: 3 | BH7: 1 | BI7: 1 | BJ7: - | BK7: 完​美 | BL7: 13 | BM7: - | BO7: - | BP7: 47664 | BQ7: 无 | BR7: 低​伤病​风险
A8: - | C8: 哈里·马奎尔 - 选​择球​员 | D8: 度​假 | E8: 1 | F8: 0 | G8: 很​好 | H8: 后​卫 (中) | I8: 32 | J8: 148 | K8: 158 | L8: 13 | M8: 7 | N8: 15 | O8: 14 | P8: 13 | Q8: 5 | R8: 10 | S8: 10 | T8: 15 | U8: 8 | V8: 8 | W8: 14 | X8: 17 | Y8: 7 | Z8: 9 | AA8: 16 | AB8: 12 | AC8: 14 | AD8: 12 | AE8: 15 | AF8: 14 | AG8: 12 | AH8: 14 | AI8: 7 | AJ8: 11 | AK8: 17 | AL8: 14 | AM8: 13 | AN8: 10 | AO8: 17 | AP8: 13 | AQ8: 17 | AR8: 13 | AS8: 17 | AT8: 12 | AU8: 17 | AV8: 12 | AW8: 13 | AX8: 11 | AY8: 4 | AZ8: 2 | BA8: 2 | BB8: 3 | BC8: 2 | BD8: 3 | BE8: 3 | BF8: 2 | BG8: 2 | BH8: 2 | BI8: 2 | BJ8: - | BK8: 完​美 | BL8: 16 | BM8: - | BO8: 21 | BP8: 46203 | BQ8: 无 | BR8: 低​伤病​风险
A9: - | C9: 梅森·蒙特 - 选​择球​员 | D9: 度​假 | E9: 1 | F9: 0 | G9: 好 | H9: 中​场 (中), 攻​中场 (右左中) | I9: 26 | J9: 150 | K9: 165 | L9: 14 | M9: 12 | N9: 7 | O9: 15 | P9: 14 | Q9: 15 | R9: 4 | S9: 11 | T9: 10 | U9: 14 | V9: 13 | W9: 15 | X9: 6 | Y9: 12 | Z9: 13 | AA9: 14 | AB9: 19 | AC9: 14 | AD9: 14 | AE9: 10 | AF9: 15 | AG9: 12 | AH9: 18 | AI9: 16 | AJ9: 17 | AK9: 15 | AL9: 13 | AM9: 13 | AN9: 14 | AO9: 8 | AP9: 15 | AQ9: 18 | AR9: 11 | AS9: 10 | AT9: 15 | AU9: 13 | AV9: 12 | AW9: 14 | AX9: 14 | AY9: 1 | AZ9: 1 | BA9: 2 | BB9: 3 | BC9: 1 | BD9: 1 | BE9: 3 | BF9: 4 | BG9: 1 | BH9: 3 | BI9: 4 | BJ9: - | BK9: 完​美 | BL9: 16 | BM9: - | BO9: 43 | BP9: 46934 | BQ9: 无 | BR9: 低​伤病​风险
A10: - | C10: 德莫特·米 - 选​择球​员 | D10: 度​假 | E10: 0.95 | F10: 0 | G10: 差 | H10: 门​将 | I10: 22 | J10: 76 | K10: 94 | L10: 6 | M10: 1 | N10: 3 | O10: 3 | P10: 8 | Q10: 3 | R10: 3 | S10: 2 | T10: 1 | U10: 6 | V10: 2 | W10: 8 | X10: 2 | Y10: 1 | Z10: 1 | AA10: 11 | AB10: 7 | AC10: 10 | AD10: 9 | AE10: 7 | AF10: 11 | AG10: 4 | AH10: 9 | AI10: 3 | AJ10: 3 | AK10: 10 | AL10: 11 | AM10: 8 | AN10: 11 | AO10: 13 | AP10: 12 | AQ10: 7 | AR10: 10 | AS10: 8 | AT10: 7 | AU10: 7 | AV10: 19 | AW10: 15 | AX10: 13 | AY10: 8 | AZ10: 9 | BA10: 13 | BB10: 9 | BC10: 6 | BD10: 12 | BE10: 6 | BF10: 8 | BG10: 5 | BH10: 8 | BI10: 14 | BJ10: - | BK10: 优​秀 | BL10: 8 | BM10: - | BO10: - | BP10: 46203 | BQ10: 无 | BR10: 低​伤病​风险
A11: - | C11: 卢克·肖 - 选​择球​员 | D11: 度​假 | E11: 1 | F11: 0 | G11: 有​点差 | H11: 后​卫 (左中) | I11: 29 | J11: 152 | K11: 162 | L11: 15 | M11: 14 | N11: 14 | O11: 10 | P11: 14 | Q11: 15 | R11: 10 | S11: 14 | T11: 13 | U11: 14 | V11: 8 | W11: 15 | X11: 13 | Y11: 6 | Z11: 10 | AA11: 15 | AB11: 13 | AC11: 13 | AD11: 14 | AE11: 12 | AF11: 13 | AG11: 13 | AH11: 15 | AI11: 14 | AJ11: 10 | AK11: 13 | AL11: 15 | AM11: 15 | AN11: 14 | AO11: 14 | AP11: 15 | AQ11: 14 | AR11: 15 | AS11: 16 | AT11: 14 | AU11: 10 | AV11: 14 | AW11: 13 | AX11: 13 | AY11: 3 | AZ11: 3 | BA11: 1 | BB11: 1 | BC11: 3 | BD11: 1 | BE11: 1 | BF11: 1 | BG11: 1 | BH11: 1 | BI11: 2 | BJ11: - | BK11: 完​美 | BL11: 11 | BM11: - | BO11: 3 | BP11: 46568 | BQ11: 无 | BR11: 低​伤病​风险
A12: - | C12: 诺赛尔·马兹拉乌 - 选​择球​员 | D12: 度​假 | E12: 1 | F12: 0 | G12: 很​好 | H12: 后​卫 (右左中), 边翼​卫 (右) | I12: 27 | J12: 149 | K12: 155 | L12: 14 | M12: 12 | N12: 11 | O12: 10 | P12: 16 | Q12: 8 | R12: 12 | S12: 14 | T12: 14 | U12: 7 | V12: 9 | W12: 15 | X12: 11 | Y12: 12 | Z12: 15 | AA12: 12 | AB12: 16 | AC12: 12 | AD12: 14 | AE12: 12 | AF12: 13 | AG12: 14 | AH12: 16 | AI12: 14 | AJ12: 12 | AK12: 14 | AL12: 13 | AM12: 14 | AN12: 14 | AO12: 11 | AP12: 14 | AQ12: 15 | AR12: 12 | AS12: 10 | AT12: 14 | AU12: 13 | AV12: 13 | AW12: 12 | AX12: 12 | AY12: 2 | AZ12: 2 | BA12: 2 | BB12: 4 | BC12: 2 | BD12: 2 | BE12: 2 | BF12: 2 | BG12: 2 | BH12: 2 | BI12: 2 | BJ12: - | BK12: 完​美 | BL12: 12 | BM12: - | BO12: 19 | BP12: 46934 | BQ12: 无 | BR12: 低​伤病​风险
A13: - | C13: 马泰斯·德·莱特 - 选​择球​员 | D13: 度​假 | E13: 1 | F13: 0 | G13: 很​好 | H13: 后​卫 (中) | I13: 25 | J13: 155 | K13: 173 | L13: 13 | M13: 5 | N13: 16 | O13: 8 | P13: 12 | Q13: 4 | R13: 8 | S13: 9 | T13: 16 | U13: 8 | V13: 8 | W13: 12 | X13: 16 | Y13: 10 | Z13: 5 | AA13: 16 | AB13: 15 | AC13: 14 | AD13: 13 | AE13: 14 | AF13: 16 | AG13: 10 | AH13: 15 | AI13: 7 | AJ13: 16 | AK13: 18 | AL13: 14 | AM13: 11 | AN13: 12 | AO13: 16 | AP13: 15 | AQ13: 13 | AR13: 16 | AS13: 18 | AT13: 14 | AU13: 11 | AV13: 14 | AW13: 14 | AX13: 14 | AY13: 3 | AZ13: 2 | BA13: 3 | BB13: 3 | BC13: 3 | BD13: 1 | BE13: 2 | BF13: 1 | BG13: 1 | BH13: 3 | BI13: 2 | BJ13: - | BK13: 完​美 | BL13: 19 | BM13: - | BO13: 20 | BP13: 47299 | BQ13: 无 | BR13: 低​伤病​风险
A14: - | C14: 蒂雷尔·马拉西亚 - 选​择球​员 | D14: 度​假 | E14: 1 | F14: 0 | G14: 差 | H14: 后​卫 (左) | I14: 25 | J14: 134 | K14: 150 | L14: 12 | M14: 13 | N14: 14 | O14: 7 | P14: 13 | Q14: 7 | R14: 12 | S14: 12 | T14: 13 | U14: 9 | V14: 7 | W14: 13 | X14: 9 | Y14: 8 | Z14: 10 | AA14: 12 | AB14: 16 | AC14: 11 | AD14: 14 | AE14: 9 | AF14: 15 | AG14: 9 | AH14: 15 | AI14: 13 | AJ14: 16 | AK14: 15 | AL14: 12 | AM14: 13 | AN14: 15 | AO14: 8 | AP14: 16 | AQ14: 15 | AR14: 13 | AS14: 7 | AT14: 15 | AU14: 16 | AV14: 13 | AW14: 13 | AX14: 15 | AY14: 3 | AZ14: 2 | BA14: 3 | BB14: 2 | BC14: 1 | BD14: 1 | BE14: 3 | BF14: 3 | BG14: 2 | BH14: 2 | BI14: 1 | BJ14: - | BK14: 完​美 | BL14: 14 | BM14: - | BO14: 4 | BP14: 46203 | BQ14: 无 | BR14: 低​伤病​风险
A15: - | C15: 约书亚·奇科琦 - 选​择球​员 | D15: 度​假 | E15: 1 | F15: 0 | G15: 很​好 | H15: 攻​中场 (中), 前​锋 (中) | I15: 24 | J15: 142 | K15: 160 | L15: 16 | M15: 9 | N15: 5 | O15: 13 | P15: 18 | Q15: 4 | R15: 3 | S15: 17 | T15: 6 | U15: 11 | V15: 13 | W15: 15 | X15: 12 | Y15: 12 | Z15: 19 | AA15: 6 | AB15: 12 | AC15: 13 | AD15: 14 | AE15: 9 | AF15: 8 | AG15: 16 | AH15: 18 | AI15: 14 | AJ15: 13 | AK15: 9 | AL15: 15 | AM15: 13 | AN15: 12 | AO15: 13 | AP15: 13 | AQ15: 14 | AR15: 13 | AS15: 14 | AT15: 12 | AU15: 15 | AV15: 12 | AW15: 14 | AX15: 11 | AY15: 1 | AZ15: 1 | BA15: 1 | BB15: 3 | BC15: 3 | BD15: 3 | BE15: 2 | BF15: 3 | BG15: 1 | BH15: 1 | BI15: 2 | BJ15: - | BK15: 完​美 | BL15: 13 | BM15: - | BO15: 28 | BP15: 47299 | BQ15: 无 | BR15: 低​伤病​风险
A16: - | C16: 布鲁诺·费尔南德斯 - 选​择球​员 | D16: 度​假 | E16: 1 | F16: 0 | G16: 好 | H16: 后​腰, 中​场/攻​中场 (中) | I16: 30 | J16: 175 | K16: 176 | L16: 18 | M16: 16 | N16: 3 | O16: 19 | P16: 18 | Q16: 16 | R16: 3 | S16: 11 | T16: 8 | U16: 16 | V16: 15 | W16: 17 | X16: 9 | Y16: 15 | Z16: 17 | AA16: 7 | AB16: 18 | AC16: 13 | AD16: 13 | AE16: 17 | AF16: 18 | AG16: 18 | AH16: 15 | AI16: 16 | AJ16: 18 | AK16: 15 | AL16: 17 | AM16: 14 | AN16: 13 | AO16: 9 | AP16: 15 | AQ16: 20 | AR16: 13 | AS16: 10 | AT16: 13 | AU16: 20 | AV16: 14 | AW16: 12 | AX16: 14 | AY16: 3 | AZ16: 2 | BA16: 1 | BB16: 3 | BC16: 1 | BD16: 1 | BE16: 3 | BF16: 2 | BG16: 2 | BH16: 2 | BI16: 1 | BJ16: - | BK16: 完​美 | BL16: 18 | BM16: - | BO16: 103 | BP16: 46568 | BQ16: 无 | BR16: 低​伤病​风险
A17: - | C17: 阿马德·达里奥·特拉奥雷 - 选​择球​员 | D17: 度​假 | E17: 1 | F17: 0 | G17: 稍​差 | H17: 边翼​卫/中​场 (右), 攻​中场 (右中) | I17: 22 | J17: 150 | K17: 166 | L17: 15 | M17: 11 | N17: 6 | O17: 8 | P17: 16 | Q17: 15 | R17: 2 | S17: 15 | T17: 6 | U17: 12 | V17: 13 | W17: 16 | X17: 3 | Y17: 14 | Z17: 16 | AA17: 9 | AB17: 16 | AC17: 11 | AD17: 13 | AE17: 5 | AF17: 14 | AG17: 13 | AH17: 13 | AI17: 14 | AJ17: 17 | AK17: 12 | AL17: 12 | AM17: 14 | AN17: 16 | AO17: 6 | AP17: 15 | AQ17: 14 | AR17: 14 | AS17: 9 | AT17: 15 | AU17: 15 | AV17: 12 | AW17: 14 | AX17: 14 | AY17: 2 | AZ17: 2 | BA17: 3 | BB17: 3 | BC17: 3 | BD17: 1 | BE17: 2 | BF17: 1 | BG17: 2 | BH17: 1 | BI17: 3 | BJ17: - | BK17: 完​美 | BL17: 16 | BM17: - | BO17: 17 | BP17: 47664 | BQ17: 无 | BR17: 低​伤病​风险
A18: - | C18: 布里安·姆贝乌莫 - 选​择球​员 | D18: 度​假 | E18: 1 | F18: 0 | G18: 完​美 | H18: 攻​中场 (右左中), 前​锋 (中) | I18: 25 | J18: 155 | K18: 160 | L18: 13 | M18: 13 | N18: 6 | O18: 17 | P18: 15 | Q18: 12 | R18: 6 | S18: 15 | T18: 6 | U18: 12 | V18: 14 | W18: 17 | X18: 8 | Y18: 13 | Z18: 15 | AA18: 7 | AB18: 17 | AC18: 13 | AD18: 14 | AE18: 8 | AF18: 12 | AG18: 13 | AH18: 14 | AI18: 14 | AJ18: 17 | AK18: 13 | AL18: 13 | AM18: 15 | AN18: 15 | AO18: 8 | AP18: 16 | AQ18: 15 | AR18: 13 | AS18: 13 | AT18: 15 | AU18: 17 | AV18: 15 | AW18: 15 | AX18: 13 | AY18: 2 | AZ18: 2 | BA18: 4 | BB18: 3 | BC18: 1 | BD18: 1 | BE18: 1 | BF18: 3 | BG18: 3 | BH18: 2 | BI18: 3 | BJ18: - | BK18: 完​美 | BL18: 15 | BM18: - | BO18: 47 | BP18: 47664 | BQ18: 无 | BR18: 低​伤病​风险
A19: - | C19: 本杰明·塞斯卡 - 选​择球​员 | D19: 度​假 | E19: 1 | F19: 0 | G19: 还​不错 | H19: 前​锋 (中) | I19: 22 | J19: 148 | K19: 170 | L19: 12 | M19: 7 | N19: 7 | O19: 17 | P19: 14 | Q19: 3 | R19: 8 | S19: 14 | T19: 8 | U19: 10 | V19: 14 | W19: 13 | X19: 15 | Y19: 14 | Z19: 14 | AA19: 7 | AB19: 14 | AC19: 12 | AD19: 13 | AE19: 10 | AF19: 13 | AG19: 11 | AH19: 12 | AI19: 14 | AJ19: 15 | AK19: 14 | AL19: 14 | AM19: 12 | AN19: 14 | AO19: 17 | AP19: 15 | AQ19: 15 | AR19: 15 | AS19: 15 | AT19: 16 | AU19: 16 | AV19: 13 | AW19: 12 | AX19: 12 | AY19: 1 | AZ19: 3 | BA19: 3 | BB19: 1 | BC19: 1 | BD19: 1 | BE19: 2 | BF19: 3 | BG19: 1 | BH19: 3 | BI19: 3 | BJ19: - | BK19: 完​美 | BL19: 13 | BM19: - | BO19: 43 | BP19: 47664 | BQ19: 无 | BR19: 低​伤病​风险
A20: - | C20: 阿尔泰·贝蒂儿 - 选​择球​员 | D20: 度​假 | E20: 1 | F20: 0 | G20: 极​好 | H20: 门​将 | I20: 27 | J20: 125 | K20: 141 | L20: 12 | M20: 3 | N20: 3 | O20: 1 | P20: 10 | Q20: 5 | R20: 2 | S20: 2 | T20: 3 | U20: 9 | V20: 2 | W20: 11 | X20: 8 | Y20: 2 | Z20: 4 | AA20: 14 | AB20: 14 | AC20: 7 | AD20: 9 | AE20: 11 | AF20: 16 | AG20: 5 | AH20: 10 | AI20: 1 | AJ20: 12 | AK20: 10 | AL20: 15 | AM20: 10 | AN20: 13 | AO20: 17 | AP20: 19 | AQ20: 13 | AR20: 14 | AS20: 16 | AT20: 12 | AU20: 14 | AV20: 11 | AW20: 12 | AX20: 10 | AY20: 14 | AZ20: 15 | BA20: 15 | BB20: 8 | BC20: 13 | BD20: 15 | BE20: 12 | BF20: 15 | BG20: 13 | BH20: 10 | BI20: 16 | BJ20: - | BK20: 完​美 | BL20: 12 | BM20: - | BO20: - | BP20: 46568 | BQ20: 无 | BR20: 低​伤病​风险
A21: - | C21: 曼努埃尔·乌加特 - 选​择球​员 | D21: 度​假 | E21: 1 | F21: 0 | G21: 很​好 | H21: 后​腰, 中​场 (中) | I21: 24 | J21: 140 | K21: 152 | L21: 12 | M21: 8 | N21: 13 | O21: 7 | P21: 12 | Q21: 7 | R21: 10 | S21: 11 | T21: 18 | U21: 6 | V21: 8 | W21: 12 | X21: 10 | Y21: 9 | Z21: 12 | AA21: 13 | AB21: 17 | AC21: 15 | AD21: 12 | AE21: 10 | AF21: 18 | AG21: 8 | AH21: 17 | AI21: 8 | AJ21: 15 | AK21: 18 | AL21: 16 | AM21: 9 | AN21: 13 | AO21: 10 | AP21: 13 | AQ21: 17 | AR21: 16 | AS21: 14 | AT21: 13 | AU21: 17 | AV21: 12 | AW21: 14 | AX21: 13 | AY21: 1 | AZ21: 2 | BA21: 1 | BB21: 2 | BC21: 2 | BD21: 1 | BE21: 2 | BF21: 2 | BG21: 2 | BH21: 2 | BI21: 3 | BJ21: - | BK21: 完​美 | BL21: 15 | BM21: - | BO21: 3 | BP21: 47299 | BQ21: 无 | BR21: 低​伤病​风险
A22: - | C22: 迪奥戈·达洛特 - 选​择球​员 | D22: 度​假 | E22: 1 | F22: 0 | G22: 较​好 | H22: 后​卫 (右左), 边翼​卫 (右) | I22: 26 | J22: 144 | K22: 155 | L22: 13 | M22: 13 | N22: 12 | O22: 10 | P22: 14 | Q22: 8 | R22: 15 | S22: 13 | T22: 13 | U22: 6 | V22: 8 | W22: 14 | X22: 12 | Y22: 8 | Z22: 11 | AA22: 14 | AB22: 15 | AC22: 11 | AD22: 10 | AE22: 10 | AF22: 13 | AG22: 10 | AH22: 14 | AI22: 14 | AJ22: 13 | AK22: 12 | AL22: 13 | AM22: 12 | AN22: 14 | AO22: 13 | AP22: 16 | AQ22: 15 | AR22: 14 | AS22: 14 | AT22: 15 | AU22: 15 | AV22: 12 | AW22: 13 | AX22: 12 | AY22: 2 | AZ22: 4 | BA22: 1 | BB22: 1 | BC22: 1 | BD22: 3 | BE22: 1 | BF22: 2 | BG22: 3 | BH22: 1 | BI22: 3 | BJ22: - | BK22: 完​美 | BL22: 14 | BM22: - | BO22: 4 | BP22: 46934 | BQ22: 无 | BR22: 低​伤病​风险
A23: - | C23: 考比·梅诺 - 选​择球​员 | D23: 度​假 | E23: 1 | F23: 0 | G23: 较​差 | H23: 后​腰, 中​场/攻​中场 (中) | I23: 20 | J23: 147 | K23: 162 | L23: 14 | M23: 9 | N23: 9 | O23: 13 | P23: 16 | Q23: 9 | R23: 4 | S23: 14 | T23: 12 | U23: 8 | V23: 13 | W23: 15 | X23: 10 | Y23: 9 | Z23: 12 | AA23: 12 | AB23: 14 | AC23: 12 | AD23: 14 | AE23: 7 | AF23: 13 | AG23: 13 | AH23: 15 | AI23: 14 | AJ23: 13 | AK23: 13 | AL23: 14 | AM23: 16 | AN23: 13 | AO23: 12 | AP23: 14 | AQ23: 14 | AR23: 16 | AS23: 12 | AT23: 13 | AU23: 15 | AV23: 13 | AW23: 14 | AX23: 15 | AY23: 1 | AZ23: 2 | BA23: 3 | BB23: 4 | BC23: 1 | BD23: 1 | BE23: 3 | BF23: 1 | BG23: 1 | BH23: 2 | BI23: 3 | BJ23: - | BK23: 完​美 | BL23: 16 | BM23: - | BO23: - | BP23: 46568 | BQ23: 无 | BR23: 低​伤病​风险
A24: - | C24: 莱尼·约罗 - 选​择球​员 | D24: 度​假 | E24: 1 | F24: 0 | G24: 很​好 | H24: 后​卫 (中) | I24: 19 | J24: 142 | K24: 168 | L24: 13 | M24: 5 | N24: 13 | O24: 10 | P24: 13 | Q24: 5 | R24: 5 | S24: 12 | T24: 13 | U24: 5 | V24: 6 | W24: 14 | X24: 15 | Y24: 9 | Z24: 11 | AA24: 14 | AB24: 13 | AC24: 13 | AD24: 13 | AE24: 10 | AF24: 9 | AG24: 12 | AH24: 13 | AI24: 8 | AJ24: 16 | AK24: 13 | AL24: 14 | AM24: 14 | AN24: 16 | AO24: 15 | AP24: 15 | AQ24: 14 | AR24: 13 | AS24: 13 | AT24: 15 | AU24: 12 | AV24: 12 | AW24: 17 | AX24: 15 | AY24: 2 | AZ24: 2 | BA24: 2 | BB24: 2 | BC24: 3 | BD24: 4 | BE24: 4 | BF24: 3 | BG24: 1 | BH24: 2 | BI24: 3 | BJ24: - | BK24: 完​美 | BL24: 16 | BM24: - | BO24: - | BP24: 47299 | BQ24: 无 | BR24: 低​伤病​风险
A25: - | C25: 艾登·希文 - 选​择球​员 | D25: 度​假 | E25: 1 | F25: 0 | G25: 高​昂 | H25: 后​卫 (中), 后​腰 | I25: 18 | J25: 137 | K25: 150 | L25: 13 | M25: 6 | N25: 14 | O25: 7 | P25: 13 | Q25: 5 | R25: 10 | S25: 10 | T25: 14 | U25: 5 | V25: 5 | W25: 14 | X25: 13 | Y25: 3 | Z25: 5 | AA25: 13 | AB25: 13 | AC25: 11 | AD25: 13 | AE25: 7 | AF25: 10 | AG25: 9 | AH25: 14 | AI25: 7 | AJ25: 14 | AK25: 13 | AL25: 14 | AM25: 15 | AN25: 15 | AO25: 14 | AP25: 13 | AQ25: 14 | AR25: 15 | AS25: 13 | AT25: 15 | AU25: 15 | AV25: 13 | AW25: 9 | AX25: 15 | AY25: 1 | AZ25: 2 | BA25: 2 | BB25: 2 | BC25: 2 | BD25: 3 | BE25: 3 | BF25: 2 | BG25: 2 | BH25: 3 | BI25: 3 | BJ25: - | BK25: 完​美 | BL25: 13 | BM25: - | BO25: - | BP25: 47299 | BQ25: 无 | BR25: 低​伤病​风险
A26: 以上是曼联
A27: 位​置/角​色/职​责 | C27: 球​员 | D27: 现​状 | F27: 疲劳值(N) | G27: 士​气 | H27: 位​置 | I27: 年​龄 | J27: 能​力 | K27: 潜​力 | L27: 传​球 | M27: 传​中 | N27: 盯​人 | O27: 点​球 | P27: 技​术 | Q27: 角​球 | R27: 界​外球 | S27: 盘​带 | T27: 抢​断 | U27: 任​意球 | V27: 射​门 | W27: 停​球 | X27: 头​球 | Y27: 远​射 | Z27: 才​华 | AA27: 位​置 | AB27: 投​入 | AC27: 集​中 | AD27: 决​断 | AE27: 领​导力 | AF27: 侵​略 | AG27: 视​野 | AH27: 合​作 | AI27: 无​球跑 | AJ27: 意​志 | AK27: 勇​敢 | AL27: 预​判 | AM27: 镇​定 | AN27: 爆​发 | AO27: 弹​跳 | AP27: 灵​活 | AQ27: 耐​力 | AR27: 平​衡 | AS27: 强​壮 | AT27: 速​度 | AU27: 体​质 | AV27: 稳​定 | AW27: 大​赛发​挥 | AX27: 抗​压 | AY27: 出​击 | AZ27: 开​球 | BA27: 反​应 | BB27: 拦​截传​中 | BC27: 击​球 | BD27: 手​控球 | BE27: 手​抛球 | BF27: 一​对一 | BG27: 意​外 | BH27: 指​挥 | BI27: 制​空 | BJ27: 平​均评​分 | BK27: 体​况 | BL27: 职​业素​养 | BM27: 出​场 | BN27: 总​体满​意度 | BO27: 总​联赛​进球 | BP27: 到​期 | BQ27: 训​练负​荷 | BR27: 总​体风​险
A28: - | C28: 杰里米·多库 - 选​择球​员 | E28: 0.96 | F28: 0 | G28: 完​美 | H28: 攻​中场 (右左), 前​锋 (中) | I28: 23 | J28: 166 | K28: 175 | L28: 14 | M28: 12 | N28: 5 | O28: 14 | P28: 15 | Q28: 11 | R28: 5 | S28: 18 | T28: 7 | U28: 8 | V28: 11 | W28: 13 | X28: 5 | Y28: 9 | Z28: 17 | AA28: 8 | AB28: 14 | AC28: 13 | AD28: 16 | AE28: 6 | AF28: 13 | AG28: 13 | AH28: 15 | AI28: 13 | AJ28: 12 | AK28: 13 | AL28: 13 | AM28: 13 | AN28: 19 | AO28: 8 | AP28: 13 | AQ28: 13 | AR28: 13 | AS28: 14 | AT28: 16 | AU28: 15 | AV28: 14 | AW28: 13 | AX28: 13 | AY28: 1 | AZ28: 1 | BA28: 3 | BB28: 1 | BC28: 2 | BD28: 1 | BE28: 1 | BF28: 3 | BG28: 1 | BH28: 1 | BI28: 1 | BJ28: 7 | BK28: 完​美 | BL28: 11 | BM28: 0 (1) | BO28: 15 | BP28: 46934 | BQ28: 无 | BR28: 低​伤病​风险
A29: - | C29: 马特奥·科瓦契奇 - 选​择球​员 | E29: 0.95 | F29: 0 | G29: 好 | H29: 后​腰, 中​场 (中) | I29: 31 | J29: 151 | K29: 172 | L29: 14 | M29: 10 | N29: 12 | O29: 12 | P29: 16 | Q29: 10 | R29: 7 | S29: 16 | T29: 15 | U29: 12 | V29: 8 | W29: 16 | X29: 10 | Y29: 9 | Z29: 14 | AA29: 13 | AB29: 17 | AC29: 11 | AD29: 14 | AE29: 11 | AF29: 14 | AG29: 15 | AH29: 15 | AI29: 13 | AJ29: 17 | AK29: 14 | AL29: 15 | AM29: 17 | AN29: 15 | AO29: 9 | AP29: 13 | AQ29: 14 | AR29: 16 | AS29: 13 | AT29: 14 | AU29: 12 | AV29: 13 | AW29: 13 | AX29: 14 | AY29: 1 | AZ29: 2 | BA29: 1 | BB29: 2 | BC29: 1 | BD29: 2 | BE29: 2 | BF29: 1 | BG29: 3 | BH29: 1 | BI29: 2 | BJ29: 6.5 | BK29: 优​秀 | BL29: 16 | BM29: 0 (2) | BO29: 16 | BP29: 46568 | BQ29: 无 | BR29: 低​伤病​风险
A30: - | C30: 约什科·格瓦迪奥尔 - 选​择球​员 | E30: 0.91 | F30: 0 | G30: 完​美 | H30: 后​卫 (左中), 边翼​卫 (左) | I30: 23 | J30: 159 | K30: 180 | L30: 16 | M30: 12 | N30: 14 | O30: 7 | P30: 14 | Q30: 2 | R30: 12 | S30: 13 | T30: 14 | U30: 6 | V30: 12 | W30: 14 | X30: 15 | Y30: 8 | Z30: 13 | AA30: 14 | AB30: 16 | AC30: 15 | AD30: 14 | AE30: 13 | AF30: 15 | AG30: 15 | AH30: 15 | AI30: 13 | AJ30: 17 | AK30: 17 | AL30: 14 | AM30: 16 | AN30: 14 | AO30: 13 | AP30: 16 | AQ30: 15 | AR30: 15 | AS30: 16 | AT30: 15 | AU30: 15 | AV30: 14 | AW30: 16 | AX30: 18 | AY30: 1 | AZ30: 2 | BA30: 1 | BB30: 1 | BC30: 2 | BD30: 1 | BE30: 2 | BF30: 1 | BG30: 2 | BH30: 1 | BI30: 3 | BJ30: 7.6 | BK30: 优​秀 | BL30: 16 | BM30: 2 | BO30: 6 | BP30: 46934 | BQ30: 无 | BR30: 低​伤病​风险
A31: - | C31: 马库斯·贝蒂奈里 - 选​择球​员 | D31: 注​册 | E31: 1 | F31: 0 | G31: 高​昂 | H31: 门​将 | I31: 33 | J31: 117 | K31: 130 | L31: 12 | M31: 3 | N31: 5 | O31: 1 | P31: 8 | Q31: 3 | R31: 14 | S31: 5 | T31: 5 | U31: 7 | V31: 2 | W31: 9 | X31: 6 | Y31: 3 | Z31: 3 | AA31: 14 | AB31: 11 | AC31: 13 | AD31: 11 | AE31: 13 | AF31: 11 | AG31: 6 | AH31: 14 | AI31: 2 | AJ31: 18 | AK31: 14 | AL31: 14 | AM31: 10 | AN31: 10 | AO31: 16 | AP31: 9 | AQ31: 11 | AR31: 12 | AS31: 13 | AT31: 6 | AU31: 8 | AV31: 9 | AW31: 10 | AX31: 12 | AY31: 11 | AZ31: 13 | BA31: 13 | BB31: 12 | BC31: 14 | BD31: 11 | BE31: 12 | BF31: 12 | BG31: 5 | BH31: 12 | BI31: 15 | BJ31: - | BK31: 完​美 | BL31: 15 | BM31: - | BO31: - | BP31: 46203 | BQ31: 无 | BR31: 低​伤病​风险
A32: - | C32: 约翰·斯通斯 - 选​择球​员 | D32: 受​伤 | E32: 0.76 | F32: 0 | G32: 高​昂 | H32: 后​卫 (右中), 后​腰 | I32: 31 | J32: 162 | K32: 170 | L32: 16 | M32: 6 | N32: 13 | O32: 12 | P32: 16 | Q32: 4 | R32: 8 | S32: 14 | T32: 16 | U32: 5 | V32: 8 | W32: 14 | X32: 14 | Y32: 6 | Z32: 12 | AA32: 15 | AB32: 17 | AC32: 16 | AD32: 15 | AE32: 13 | AF32: 13 | AG32: 14 | AH32: 16 | AI32: 15 | AJ32: 13 | AK32: 17 | AL32: 15 | AM32: 17 | AN32: 14 | AO32: 16 | AP32: 13 | AQ32: 15 | AR32: 12 | AS32: 15 | AT32: 15 | AU32: 15 | AV32: 16 | AW32: 14 | AX32: 14 | AY32: 3 | AZ32: 1 | BA32: 3 | BB32: 1 | BC32: 1 | BD32: 3 | BE32: 1 | BF32: 2 | BG32: 2 | BH32: 1 | BI32: 2 | BJ32: 6.5 | BK32: 出​色 | BL32: 15 | BM32: 1 | BO32: 8 | BP32: 46203 | BQ32: 无 | BR32: 低​伤病​风险
A33: - | C33: 马科·盖希 - 选​择球​员 | E33: 0.92 | F33: 0 | G33: 超​凡 | H33: 后​卫 (中) | I33: 24 | J33: 165 | K33: 168 | L33: 14 | M33: 12 | N33: 16 | O33: 7 | P33: 15 | Q33: 5 | R33: 9 | S33: 14 | T33: 15 | U33: 7 | V33: 8 | W33: 15 | X33: 14 | Y33: 8 | Z33: 11 | AA33: 15 | AB33: 14 | AC33: 14 | AD33: 15 | AE33: 17 | AF33: 11 | AG33: 13 | AH33: 15 | AI33: 10 | AJ33: 17 | AK33: 14 | AL33: 15 | AM33: 15 | AN33: 15 | AO33: 14 | AP33: 14 | AQ33: 15 | AR33: 15 | AS33: 14 | AT33: 14 | AU33: 16 | AV33: 16 | AW33: 14 | AX33: 15 | AY33: 3 | AZ33: 2 | BA33: 1 | BB33: 1 | BC33: 3 | BD33: 3 | BE33: 2 | BF33: 3 | BG33: 2 | BH33: 1 | BI33: 3 | BJ33: 7.35 | BK33: 优​秀 | BL33: 18 | BM33: 2 | BO33: 3 | BP33: 48029 | BQ33: 无 | BR33: 低​伤病​风险
A34: - | C34: 菲尔·福登 - 选​择球​员 | E34: 0.88 | F34: 0 | G34: 完​美 | H34: 中​场 (中), 攻​中场 (右左中) | I34: 25 | J34: 169 | K34: 180 | L34: 17 | M34: 13 | N34: 8 | O34: 12 | P34: 17 | Q34: 13 | R34: 5 | S34: 17 | T34: 8 | U34: 13 | V34: 14 | W34: 17 | X34: 8 | Y34: 13 | Z34: 16 | AA34: 11 | AB34: 14 | AC34: 15 | AD34: 14 | AE34: 8 | AF34: 7 | AG34: 17 | AH34: 15 | AI34: 16 | AJ34: 14 | AK34: 13 | AL34: 14 | AM34: 16 | AN34: 16 | AO34: 7 | AP34: 15 | AQ34: 14 | AR34: 15 | AS34: 9 | AT34: 16 | AU34: 14 | AV34: 13 | AW34: 16 | AX34: 12 | AY34: 3 | AZ34: 2 | BA34: 1 | BB34: 3 | BC34: 2 | BD34: 2 | BE34: 1 | BF34: 3 | BG34: 2 | BH34: 2 | BI34: 3 | BJ34: 8.7 | BK34: 优​秀 | BL34: 14 | BM34: 1 | BO34: 35 | BP34: 46568 | BQ34: 无 | BR34: 低​伤病​风险
A35: - | C35: 詹姆斯·特拉福德 - 选​择球​员 | E35: 1 | F35: 0 | G35: 完​美 | H35: 门​将 | I35: 22 | J35: 138 | K35: 154 | L35: 11 | M35: 1 | N35: 2 | O35: 1 | P35: 13 | Q35: 2 | R35: 2 | S35: 5 | T35: 1 | U35: 5 | V35: 2 | W35: 9 | X35: 5 | Y35: 3 | Z35: 10 | AA35: 15 | AB35: 12 | AC35: 14 | AD35: 11 | AE35: 12 | AF35: 11 | AG35: 12 | AH35: 13 | AI35: 2 | AJ35: 12 | AK35: 14 | AL35: 11 | AM35: 11 | AN35: 13 | AO35: 15 | AP35: 12 | AQ35: 13 | AR35: 15 | AS35: 13 | AT35: 13 | AU35: 15 | AV35: 14 | AW35: 14 | AX35: 13 | AY35: 13 | AZ35: 14 | BA35: 15 | BB35: 13 | BC35: 12 | BD35: 13 | BE35: 14 | BF35: 14 | BG35: 11 | BH35: 12 | BI35: 15 | BJ35: - | BK35: 完​美 | BL35: 14 | BM35: - | BO35: - | BP35: 47664 | BQ35: 无 | BR35: 低​伤病​风险
A36: - | C36: 埃尔林·哈兰德 - 选​择球​员 | E36: 0.94 | F36: 0 | G36: 完​美 | H36: 前​锋 (中) | I36: 24 | J36: 184 | K36: 195 | L36: 13 | M36: 10 | N36: 6 | O36: 17 | P36: 14 | Q36: 7 | R36: 5 | S36: 14 | T36: 7 | U36: 13 | V36: 18 | W36: 13 | X36: 15 | Y36: 13 | Z36: 16 | AA36: 7 | AB36: 13 | AC36: 15 | AD36: 15 | AE36: 13 | AF36: 15 | AG36: 14 | AH36: 14 | AI36: 18 | AJ36: 20 | AK36: 15 | AL36: 19 | AM36: 17 | AN36: 17 | AO36: 18 | AP36: 17 | AQ36: 14 | AR36: 17 | AS36: 17 | AT36: 19 | AU36: 19 | AV36: 16 | AW36: 14 | AX36: 18 | AY36: 1 | AZ36: 1 | BA36: 1 | BB36: 3 | BC36: 3 | BD36: 1 | BE36: 3 | BF36: 2 | BG36: 1 | BH36: 2 | BI36: 2 | BJ36: 7.1 | BK36: 优​秀 | BL36: 17 | BM36: 1 (1) | BO36: 147 | BP36: 49125 | BQ36: 无 | BR36: 低​伤病​风险
A37: - | C37: 安托万·赛门约 - 选​择球​员 | D37: 兴​趣 | E37: 1 | F37: 0 | G37: 较​好 | H37: 攻​中场 (右左), 前​锋 (中) | I37: 25 | J37: 158 | K37: 161 | L37: 12 | M37: 11 | N37: 5 | O37: 10 | P37: 15 | Q37: 6 | R37: 14 | S37: 16 | T37: 7 | U37: 7 | V37: 16 | W37: 16 | X37: 10 | Y37: 13 | Z37: 17 | AA37: 7 | AB37: 12 | AC37: 11 | AD37: 13 | AE37: 8 | AF37: 14 | AG37: 13 | AH37: 13 | AI37: 15 | AJ37: 13 | AK37: 12 | AL37: 12 | AM37: 15 | AN37: 16 | AO37: 11 | AP37: 16 | AQ37: 14 | AR37: 14 | AS37: 14 | AT37: 15 | AU37: 14 | AV37: 13 | AW37: 11 | AX37: 9 | AY37: 3 | AZ37: 1 | BA37: 1 | BB37: 2 | BC37: 1 | BD37: 2 | BE37: 2 | BF37: 3 | BG37: 1 | BH37: 3 | BI37: 3 | BJ37: - | BK37: 完​美 | BL37: 12 | BM37: - | BO37: 23 | BP37: 48029 | BQ37: 无 | BR37: 低​伤病​风险
A38: - | C38: 内森·奥科 - 选​择球​员 | D38: 兴​趣 | E38: 1 | F38: 0 | G38: 好 | H38: 后​卫 (左中), 后​腰 | I38: 30 | J38: 153 | K38: 164 | L38: 14 | M38: 10 | N38: 16 | O38: 3 | P38: 14 | Q38: 2 | R38: 10 | S38: 13 | T38: 15 | U38: 6 | V38: 8 | W38: 14 | X38: 15 | Y38: 10 | Z38: 6 | AA38: 15 | AB38: 16 | AC38: 15 | AD38: 14 | AE38: 13 | AF38: 12 | AG38: 13 | AH38: 14 | AI38: 5 | AJ38: 15 | AK38: 16 | AL38: 14 | AM38: 15 | AN38: 15 | AO38: 12 | AP38: 15 | AQ38: 15 | AR38: 13 | AS38: 15 | AT38: 14 | AU38: 14 | AV38: 16 | AW38: 15 | AX38: 12 | AY38: 1 | AZ38: 3 | BA38: 3 | BB38: 2 | BC38: 3 | BD38: 2 | BE38: 3 | BF38: 2 | BG38: 2 | BH38: 1 | BI38: 1 | BJ38: - | BK38: 完​美 | BL38: 15 | BM38: - | BO38: 16 | BP38: 46568 | BQ38: 无 | BR38: 低​伤病​风险
A39: - | C39: 提亚尼·雷吉恩德斯 - 选​择球​员 | E39: 1 | F39: 0 | G39: 很​好 | H39: 后​腰, 中​场/攻​中场 (中) | I39: 26 | J39: 158 | K39: 165 | L39: 15 | M39: 12 | N39: 10 | O39: 12 | P39: 15 | Q39: 13 | R39: 8 | S39: 14 | T39: 8 | U39: 12 | V39: 14 | W39: 15 | X39: 11 | Y39: 15 | Z39: 14 | AA39: 11 | AB39: 14 | AC39: 15 | AD39: 14 | AE39: 12 | AF39: 8 | AG39: 16 | AH39: 16 | AI39: 16 | AJ39: 13 | AK39: 13 | AL39: 14 | AM39: 14 | AN39: 14 | AO39: 11 | AP39: 15 | AQ39: 15 | AR39: 14 | AS39: 12 | AT39: 14 | AU39: 15 | AV39: 14 | AW39: 13 | AX39: 14 | AY39: 3 | AZ39: 1 | BA39: 2 | BB39: 3 | BC39: 2 | BD39: 3 | BE39: 3 | BF39: 2 | BG39: 2 | BH39: 2 | BI39: 3 | BJ39: - | BK39: 完​美 | BL39: 15 | BM39: - | BO39: 26 | BP39: 47664 | BQ39: 无 | BR39: 低​伤病​风险
A40: - | C40: 詹路易吉·多纳鲁马 - 选​择球​员 | E40: 0.95 | F40: 0 | G40: 完​美 | H40: 门​将 | I40: 26 | J40: 170 | K40: 170 | L40: 13 | M40: 2 | N40: 3 | O40: 6 | P40: 7 | Q40: 7 | R40: 8 | S40: 6 | T40: 7 | U40: 8 | V40: 3 | W40: 10 | X40: 8 | Y40: 1 | Z40: 6 | AA40: 17 | AB40: 14 | AC40: 16 | AD40: 16 | AE40: 14 | AF40: 12 | AG40: 9 | AH40: 16 | AI40: 2 | AJ40: 15 | AK40: 16 | AL40: 17 | AM40: 15 | AN40: 11 | AO40: 19 | AP40: 9 | AQ40: 16 | AR40: 18 | AS40: 17 | AT40: 12 | AU40: 15 | AV40: 15 | AW40: 15 | AX40: 15 | AY40: 11 | AZ40: 15 | BA40: 19 | BB40: 16 | BC40: 15 | BD40: 17 | BE40: 14 | BF40: 18 | BG40: 9 | BH40: 15 | BI40: 16 | BJ40: 7.75 | BK40: 优​秀 | BL40: 14 | BM40: 2 | BO40: - | BP40: 47664 | BQ40: 无 | BR40: 低​伤病​风险
...

Sheet 分数 
A1: 位​置/角​色/职​责 | B1: 分数 | C1: 球​员 | D1: 现​状 | F1: 疲劳值(N) | G1: 士​气 | H1: 位​置 | I1: 年​龄 | J1: 能​力 | K1: 潜​力 | L1: 传​球 | M1: 传​中 | N1: 盯​人 | O1: 点​球 | P1: 技​术 | Q1: 角​球 | R1: 界​外球 | S1: 盘​带 | T1: 抢​断 | U1: 任​意球 | V1: 射​门 | W1: 停​球 | X1: 头​球 | Y1: 远​射 | Z1: 才​华 | AA1: 位​置 | AB1: 投​入 | AC1: 集​中 | AD1: 决​断 | AE1: 领​导力 | AF1: 侵​略 | AG1: 视​野 | AH1: 合​作 | AI1: 无​球跑 | AJ1: 意​志 | AK1: 勇​敢 | AL1: 预​判 | AM1: 镇​定 | AN1: 爆​发 | AO1: 弹​跳 | AP1: 灵​活 | AQ1: 耐​力 | AR1: 平​衡 | AS1: 强​壮 | AT1: 速​度 | AU1: 体​质 | AV1: 稳​定 | AW1: 大​赛发​挥 | AX1: 抗​压 | AY1: 出​击 | AZ1: 开​球 | BA1: 反​应 | BB1: 拦​截传​中 | BC1: 击​球 | BD1: 手​控球 | BE1: 手​抛球 | BF1: 一​对一 | BG1: 意​外 | BH1: 指​挥 | BI1: 制​空 | BJ1: 平​均评​分 | BK1: 体​况 | BL1: 职​业素​养 | BM1: 出​场 | BN1: 总​体满​意度 | BO1: 总​联赛​进球 | BP1: 到​期 | BQ1: 训​练负​荷 | BR1: 总​体风​险
A2: - | B2: =SUM(L2:AX2) -> 265.745 | C2: 汤姆·希顿 - 选​择球​员 | D2: 度​假 | E2: 1 | F2: 0 | G2: 有​点差 | H2: 门​将 | I2: 39 | J2: 120 | K2: 150 | L2: =IF( 数据!L2<=6,(数据!L2-1)*权重!B$48, IF(数据!L2<=12, 5*权重!B$48+(数据!L2-6)*权重!B$49, 5*权重!B$48+6*权重!B$49+(数据!L2-12)*权重!B$51 )) -> 3 | M2: =IF( 数据!M2<=6,(数据!M2-1)*权重!C$48, IF(数据!M2<=12, 5*权重!C$48+(数据!M2-6)*权重!C$49, 5*权重!C$48+6*权重!C$49+(数据!M2-12)*权重!C$51 )) -> 0.58 | N2: =IF( 数据!N2<=6,(数据!N2-1)*权重!D$48, IF(数据!N2<=12, 5*权重!D$48+(数据!N2-6)*权重!D$49, 5*权重!D$48+6*权重!D$49+(数据!N2-12)*权重!D$51 )) -> 0.16 | O2: =IF( 数据!O2<=6,(数据!O2-1)*权重!E$48, IF(数据!O2<=12, 5*权重!E$48+(数据!O2-6)*权重!E$49, 5*权重!E$48+6*权重!E$49+(数据!O2-12)*权重!E$51 )) -> 0 | P2: =IF( 数据!P2<=6,(数据!P2-1)*权重!F$48, IF(数据!P2<=12, 5*权重!F$48+(数据!P2-6)*权重!F$49, 5*权重!F$48+6*权重!F$49+(数据!P2-12)*权重!F$51 )) -> -3.5666667 | Q2: =IF( 数据!Q2<=6,(数据!Q2-1)*权重!G$48, IF(数据!Q2<=12, 5*权重!G$48+(数据!Q2-6)*权重!G$49, 5*权重!G$48+6*权重!G$49+(数据!Q2-12)*权重!G$51 )) -> 0 | R2: =IF( 数据!R2<=6,(数据!R2-1)*权重!H$48, IF(数据!R2<=12, 5*权重!H$48+(数据!R2-6)*权重!H$49, 5*权重!H$48+6*权重!H$49+(数据!R2-12)*权重!H$51 )) -> 0 | S2: =IF( 数据!S2<=6,(数据!S2-1)*权重!I$48, IF(数据!S2<=12, 5*权重!I$48+(数据!S2-6)*权重!I$49, 5*权重!I$48+6*权重!I$49+(数据!S2-12)*权重!I$51 )) -> 1.2 | ... Y2: =IF( 数据!Y2<=6,(数据!Y2-1)*权重!O$48, IF(数据!Y2<=12, 5*权重!O$48+(数据!Y2-6)*权重!O$49, 5*权重!O$48+6*权重!O$49+(数据!Y2-12)*权重!O$51 )) -> 0.48 | Z2: =IF( 数据!Z2<=6,(数据!Z2-1)*权重!P$48, IF(数据!Z2<=10, 5*权重!P$48+(数据!Z2-4)*权重!P$50, 5*权重!P$48+4*权重!P$50+(数据!Z2-10)*权重!P$52 ) ) -> 0 | AA2: =IF( 数据!AA2<=6,(数据!AA2-1)*权重!Q$48, IF(数据!AA2<=12, 5*权重!Q$48+(数据!AA2-6)*权重!Q$49, 5*权重!Q$48+6*权重!Q$49+(数据!AA2-12)*权重!Q$51 )) -> 5.8333333 | AB2: =IF( 数据!AB2<=6,(数据!AB2-1)*权重!R$48, IF(数据!AB2<=10, 5*权重!R$48+(数据!AB2-4)*权重!R$50, 5*权重!R$48+4*权重!R$50+(数据!AB2-10)*权重!R$52 ) ) -> 44.2 | AC2: =IF( 数据!AC2<=6,(数据!AC2-1)*权重!S$48, IF(数据!AC2<=12, 5*权重!S$48+(数据!AC2-6)*权重!S$49, 5*权重!S$48+6*权重!S$49+(数据!AC2-12)*权重!S$51 )) -> 22.916667 | AD2: =IF( 数据!AD2<=6,(数据!AD2-1)*权重!T$48, IF(数据!AD2<=12, 5*权重!T$48+(数据!AD2-6)*权重!T$49, 5*权重!T$48+6*权重!T$49+(数据!AD2-12)*权重!T$51 )) -> -0.86666667 | AE2: =IF( 数据!AE2<=6,(数据!AE2-1)*权重!U$48, IF(数据!AE2<=10, 5*权重!U$48+(数据!AE2-4)*权重!U$50, 5*权重!U$48+4*权重!U$50+(数据!AE2-10)*权重!U$52 ) ) -> 0.2 | AF2: =IF( 数据!AF2<=6,(数据!AF2-1)*权重!V$48, IF(数据!AF2<=10, 5*权重!V$48+(数据!AF2-4)*权重!V$50, 5*权重!V$48+4*权重!V$50+(数据!AF2-10)*权重!V$52 ) ) -> 6.075 | AG2: =IF( 数据!AG2<=6,(数据!AG2-1)*权重!W$48, IF(数据!AG2<=12, 5*权重!W$48+(数据!AG2-6)*权重!W$49, 5*权重!W$48+6*权重!W$49+(数据!AG2-12)*权重!W$51 )) -> 3.75 | AH2: =IF( 数据!AH2<=6,(数据!AH2-1)*权重!X$48, IF(数据!AH2<=10, 5*权重!X$48+(数据!AH2-4)*权重!X$50, 5*权重!X$48+4*权重!X$50+(数据!AH2-10)*权重!X$52 ) ) -> 0.4 | AI2: =IF( 数据!AI2<=6,(数据!AI2-1)*权重!Y$48, IF(数据!AI2<=12, 5*权重!Y$48+(数据!AI2-6)*权重!Y$49, 5*权重!Y$48+6*权重!Y$49+(数据!AI2-12)*权重!Y$51 )) -> 0.04 | AJ2: =IF( 数据!AJ2<=6,(数据!AJ2-1)*权重!Z$48, IF(数据!AJ2<=10, 5*权重!Z$48+(数据!AJ2-4)*权重!Z$50, 5*权重!Z$48+4*权重!Z$50+(数据!AJ2-10)*权重!Z$52 ) ) -> 8.6625 | AK2: =IF( 数据!AK2<=6,(数据!AK2-1)*权重!AA$48, IF(数据!AK2<=10, 5*权重!AA$48+(数据!AK2-4)*权重!AA$50, 5*权重!AA$48+4*权重!AA$50+(数据!AK2-10)*权重!AA$52 ) ) -> -1.1 | AL2: =IF( 数据!AL2<=6,(数据!AL2-1)*权重!AB$48, IF(数据!AL2<=12, 5*权重!AB$48+(数据!AL2-6)*权重!AB$49, 5*权重!AB$48+6*权重!AB$49+(数据!AL2-12)*权重!AB$51 )) -> 12.6 | AM2: =IF( 数据!AM2<=6,(数据!AM2-1)*权重!AC$48, IF(数据!AM2<=12, 5*权重!AC$48+(数据!AM2-6)*权重!AC$49, 5*权重!AC$48+6*权重!AC$49+(数据!AM2-12)*权重!AC$51 )) -> 8.2333333 | AN2: =IF( 数据!AN2<=6,(数据!AN2-1)*权重!AD$48, IF(数据!AN2<=12, 5*权重!AD$48+(数据!AN2-6)*权重!AD$49, 5*权重!AD$48+6*权重!AD$49+(数据!AN2-12)*权重!AD$51 )) -> 19.7 | AO2: =IF( 数据!AO2<=6,(数据!AO2-1)*权重!AE$48, IF(数据!AO2<=12, 5*权重!AE$48+(数据!AO2-6)*权重!AE$49, 5*权重!AE$48+6*权重!AE$49+(数据!AO2-12)*权重!AE$51 )) -> 17.7 | AP2: =IF( 数据!AP2<=6,(数据!AP2-1)*权重!AF$48, IF(数据!AP2<=12, 5*权重!AF$48+(数据!AP2-6)*权重!AF$49, 5*权重!AF$48+6*权重!AF$49+(数据!AP2-12)*权重!AF$51 )) -> 13.833333 | AQ2: =IF( 数据!AQ2<=6,(数据!AQ2-1)*权重!AG$48, IF(数据!AQ2<=12, 5*权重!AG$48+(数据!AQ2-6)*权重!AG$49, 5*权重!AG$48+6*权重!AG$49+(数据!AQ2-12)*权重!AG$51 )) -> 14.466667 | AR2: =IF( 数据!AR2<=6,(数据!AR2-1)*权重!AH$48, IF(数据!AR2<=12, 5*权重!AH$48+(数据!AR2-6)*权重!AH$49, 5*权重!AH$48+6*权重!AH$49+(数据!AR2-12)*权重!AH$51 )) -> 10.033333 | AS2: =IF( 数据!AS2<=6,(数据!AS2-1)*权重!AI$48, IF(数据!AS2<=12, 5*权重!AI$48+(数据!AS2-6)*权重!AI$49, 5*权重!AI$48+6*权重!AI$49+(数据!AS2-12)*权重!AI$51 )) -> 5.7 | ... AU2: =IF( 数据!AU2<=6,(数据!AU2-1)*权重!AK$48, IF(数据!AU2<=12, 5*权重!AK$48+(数据!AU2-6)*权重!AK$49, 5*权重!AK$48+6*权重!AK$49+(数据!AU2-12)*权重!AK$51 )) -> 14.2 | AV2: =IF( 数据!AV2<=6,(数据!AV2-1)*权重!AL$48, IF(数据!AV2<=10, 5*权重!AL$48+(数据!AV2-4)*权重!AL$50, 5*权重!AL$48+4*权重!AL$50+(数据!AV2-10)*权重!AL$52 ) ) -> 3.4 | AW2: =IF( 数据!AW2<=6,(数据!AW2-1)*权重!AM$48, IF(数据!AW2<=10, 5*权重!AM$48+(数据!AW2-4)*权重!AM$50, 5*权重!AM$48+4*权重!AM$50+(数据!AW2-10)*权重!AM$52 ) ) -> 4.95 | AX2: =IF( 数据!AX2<=6,(数据!AX2-1)*权重!AN$48, IF(数据!AX2<=10, 5*权重!AN$48+(数据!AX2-4)*权重!AN$50, 5*权重!AN$48+4*权重!AN$50+(数据!AX2-10)*权重!AN$52 ) ) -> 21.2375 | AY2: 11 | AZ2: 10 | BA2: 12 | BB2: 15 | BC2: 5 | BD2: 13 | BE2: 11 | BF2: 12 | BG2: 6 | BH2: 16 | BI2: 14 | BJ2: - | BK2: 完​美 | BL2: 17 | BM2: - | BO2: - | BP2: 46203 | BQ2: 无 | BR2: 低​伤病​风险
A3: - | B3: =SUM(L3:AX3) -> 407.9825 | C3: 利桑德罗·马丁内斯 - 选​择球​员 | D3: 度​假 | E3: 1 | F3: 0 | G3: 稍​差 | H3: 后​卫 (左中) | I3: 27 | J3: 152 | K3: 160 | L3: =IF( 数据!L3<=6,(数据!L3-1)*权重!B$48, IF(数据!L3<=12, 5*权重!B$48+(数据!L3-6)*权重!B$49, 5*权重!B$48+6*权重!B$49+(数据!L3-12)*权重!B$51 ) ) -> 4.4 | M3: =IF( 数据!M3<=6,(数据!M3-1)*权重!C$48, IF(数据!M3<=12, 5*权重!C$48+(数据!M3-6)*权重!C$49, 5*权重!C$48+6*权重!C$49+(数据!M3-12)*权重!C$51 ) ) -> 1.7 | N3: =IF( 数据!N3<=6,(数据!N3-1)*权重!D$48, IF(数据!N3<=12, 5*权重!D$48+(数据!N3-6)*权重!D$49, 5*权重!D$48+6*权重!D$49+(数据!N3-12)*权重!D$51 ) ) -> 1.37 | O3: =IF( 数据!O3<=6,(数据!O3-1)*权重!E$48, IF(数据!O3<=12, 5*权重!E$48+(数据!O3-6)*权重!E$49, 5*权重!E$48+6*权重!E$49+(数据!O3-12)*权重!E$51 ) ) -> 0 | P3: =IF( 数据!P3<=6,(数据!P3-1)*权重!F$48, IF(数据!P3<=12, 5*权重!F$48+(数据!P3-6)*权重!F$49, 5*权重!F$48+6*权重!F$49+(数据!P3-12)*权重!F$51 ) ) -> -2.35 | Q3: =IF( 数据!Q3<=6,(数据!Q3-1)*权重!G$48, IF(数据!Q3<=12, 5*权重!G$48+(数据!Q3-6)*权重!G$49, 5*权重!G$48+6*权重!G$49+(数据!Q3-12)*权重!G$51 ) ) -> 0 | R3: =IF( 数据!R3<=6,(数据!R3-1)*权重!H$48, IF(数据!R3<=12, 5*权重!H$48+(数据!R3-6)*权重!H$49, 5*权重!H$48+6*权重!H$49+(数据!R3-12)*权重!H$51 ) ) -> 0 | S3: =IF( 数据!S3<=6,(数据!S3-1)*权重!I$48, IF(数据!S3<=12, 5*权重!I$48+(数据!S3-6)*权重!I$49, 5*权重!I$48+6*权重!I$49+(数据!S3-12)*权重!I$51 ) ) -> 10.6 | ... Y3: =IF( 数据!Y3<=6,(数据!Y3-1)*权重!O$48, IF(数据!Y3<=12, 5*权重!O$48+(数据!Y3-6)*权重!O$49, 5*权重!O$48+6*权重!O$49+(数据!Y3-12)*权重!O$51 ) ) -> 1.2 | Z3: =IF( 数据!Z3<=6,(数据!Z3-1)*权重!P$48, IF(数据!Z3<=10, 5*权重!P$48+(数据!Z3-4)*权重!P$50, 5*权重!P$48+4*权重!P$50+(数据!Z3-10)*权重!P$52 ) ) -> -1.85 | AA3: =IF( 数据!AA3<=6,(数据!AA3-1)*权重!Q$48, IF(数据!AA3<=12, 5*权重!Q$48+(数据!AA3-6)*权重!Q$49, 5*权重!Q$48+6*权重!Q$49+(数据!AA3-12)*权重!Q$51 ) ) -> 7.1666667 | AB3: =IF( 数据!AB3<=6,(数据!AB3-1)*权重!R$48, IF(数据!AB3<=10, 5*权重!R$48+(数据!AB3-4)*权重!R$50, 5*权重!R$48+4*权重!R$50+(数据!AB3-10)*权重!R$52 ) ) -> 56.75 | AC3: =IF( 数据!AC3<=6,(数据!AC3-1)*权重!S$48, IF(数据!AC3<=12, 5*权重!S$48+(数据!AC3-6)*权重!S$49, 5*权重!S$48+6*权重!S$49+(数据!AC3-12)*权重!S$51 ) ) -> 20.866667 | AD3: =IF( 数据!AD3<=6,(数据!AD3-1)*权重!T$48, IF(数据!AD3<=12, 5*权重!T$48+(数据!AD3-6)*权重!T$49, 5*权重!T$48+6*权重!T$49+(数据!AD3-12)*权重!T$51 ) ) -> -1.2333333 | AE3: =IF( 数据!AE3<=6,(数据!AE3-1)*权重!U$48, IF(数据!AE3<=10, 5*权重!U$48+(数据!AE3-4)*权重!U$50, 5*权重!U$48+4*权重!U$50+(数据!AE3-10)*权重!U$52 ) ) -> -1.4 | AF3: =IF( 数据!AF3<=6,(数据!AF3-1)*权重!V$48, IF(数据!AF3<=10, 5*权重!V$48+(数据!AF3-4)*权重!V$50, 5*权重!V$48+4*权重!V$50+(数据!AF3-10)*权重!V$52 ) ) -> 8.4 | AG3: =IF( 数据!AG3<=6,(数据!AG3-1)*权重!W$48, IF(数据!AG3<=12, 5*权重!W$48+(数据!AG3-6)*权重!W$49, 5*权重!W$48+6*权重!W$49+(数据!AG3-12)*权重!W$51 ) ) -> 3.5 | AH3: =IF( 数据!AH3<=6,(数据!AH3-1)*权重!X$48, IF(数据!AH3<=10, 5*权重!X$48+(数据!AH3-4)*权重!X$50, 5*权重!X$48+4*权重!X$50+(数据!AH3-10)*权重!X$52 ) ) -> -0.05 | AI3: =IF( 数据!AI3<=6,(数据!AI3-1)*权重!Y$48, IF(数据!AI3<=12, 5*权重!Y$48+(数据!AI3-6)*权重!Y$49, 5*权重!Y$48+6*权重!Y$49+(数据!AI3-12)*权重!Y$51 ) ) -> 0.13333333 | AJ3: =IF( 数据!AJ3<=6,(数据!AJ3-1)*权重!Z$48, IF(数据!AJ3<=10, 5*权重!Z$48+(数据!AJ3-4)*权重!Z$50, 5*权重!Z$48+4*权重!Z$50+(数据!AJ3-10)*权重!Z$52 ) ) -> 11.0125 | AK3: =IF( 数据!AK3<=6,(数据!AK3-1)*权重!AA$48, IF(数据!AK3<=10, 5*权重!AA$48+(数据!AK3-4)*权重!AA$50, 5*权重!AA$48+4*权重!AA$50+(数据!AK3-10)*权重!AA$52 ) ) -> -0.575 | AL3: =IF( 数据!AL3<=6,(数据!AL3-1)*权重!AB$48, IF(数据!AL3<=12, 5*权重!AB$48+(数据!AL3-6)*权重!AB$49, 5*权重!AB$48+6*权重!AB$49+(数据!AL3-12)*权重!AB$51 ) ) -> 16.2 | AM3: =IF( 数据!AM3<=6,(数据!AM3-1)*权重!AC$48, IF(数据!AM3<=12, 5*权重!AC$48+(数据!AM3-6)*权重!AC$49, 5*权重!AC$48+6*权重!AC$49+(数据!AM3-12)*权重!AC$51 ) ) -> 9.9666667 | AN3: =IF( 数据!AN3<=6,(数据!AN3-1)*权重!AD$48, IF(数据!AN3<=12, 5*权重!AD$48+(数据!AN3-6)*权重!AD$49, 5*权重!AD$48+6*权重!AD$49+(数据!AN3-12)*权重!AD$51 ) ) -> 67.875 | AO3: =IF( 数据!AO3<=6,(数据!AO3-1)*权重!AE$48, IF(数据!AO3<=12, 5*权重!AE$48+(数据!AO3-6)*权重!AE$49, 5*权重!AE$48+6*权重!AE$49+(数据!AO3-12)*权重!AE$51 ) ) -> 12.5 | AP3: =IF( 数据!AP3<=6,(数据!AP3-1)*权重!AF$48, IF(数据!AP3<=12, 5*权重!AF$48+(数据!AP3-6)*权重!AF$49, 5*权重!AF$48+6*权重!AF$49+(数据!AP3-12)*权重!AF$51 ) ) -> 15.433333 | AQ3: =IF( 数据!AQ3<=6,(数据!AQ3-1)*权重!AG$48, IF(数据!AQ3<=12, 5*权重!AG$48+(数据!AQ3-6)*权重!AG$49, 5*权重!AG$48+6*权重!AG$49+(数据!AQ3-12)*权重!AG$51 ) ) -> 19.35 | AR3: =IF( 数据!AR3<=6,(数据!AR3-1)*权重!AH$48, IF(数据!AR3<=12, 5*权重!AH$48+(数据!AR3-6)*权重!AH$49, 5*权重!AH$48+6*权重!AH$49+(数据!AR3-12)*权重!AH$51 ) ) -> 15.733333 | AS3: =IF( 数据!AS3<=6,(数据!AS3-1)*权重!AI$48, IF(数据!AS3<=12, 5*权重!AI$48+(数据!AS3-6)*权重!AI$49, 5*权重!AI$48+6*权重!AI$49+(数据!AS3-12)*权重!AI$51 ) ) -> 8.55 | ... AU3: =IF( 数据!AU3<=6,(数据!AU3-1)*权重!AK$48, IF(数据!AU3<=12, 5*权重!AK$48+(数据!AU3-6)*权重!AK$49, 5*权重!AK$48+6*权重!AK$49+(数据!AU3-12)*权重!AK$51 ) ) -> 14.8 | AV3: =IF( 数据!AV3<=6,(数据!AV3-1)*权重!AL$48, IF(数据!AV3<=10, 5*权重!AL$48+(数据!AV3-4)*权重!AL$50, 5*权重!AL$48+4*权重!AL$50+(数据!AV3-10)*权重!AL$52 ) ) -> 2.975 | AW3: =IF( 数据!AW3<=6,(数据!AW3-1)*权重!AM$48, IF(数据!AW3<=10, 5*权重!AM$48+(数据!AW3-4)*权重!AM$50, 5*权重!AM$48+4*权重!AM$50+(数据!AW3-10)*权重!AM$52 ) ) -> 3.075 | AX3: =IF( 数据!AX3<=6,(数据!AX3-1)*权重!AN$48, IF(数据!AX3<=10, 5*权重!AN$48+(数据!AX3-4)*权重!AN$50, 5*权重!AN$48+4*权重!AN$50+(数据!AX3-10)*权重!AN$52 ) ) -> 23.75 | AY3: 3 | AZ3: 1 | BA3: 1 | BB3: 3 | BC3: 3 | BD3: 1 | BE3: 1 | BF3: 1 | BG3: 3 | BH3: 2 | BI3: 2 | BJ3: - | BK3: 完​美 | BL3: 14 | BM3: - | BO3: 10 | BP3: 46568 | BQ3: 无 | BR3: 低​伤病​风险
